Workbook

Sheet Balance
C1: RES | D1: 2 | E1: 6 | F1: 8 | G1: 6 | H1: 2 | I1: GMS | J1: PCN | K1: MCA | L1: REV | M1: ARW | N1: EXP | O1: GEN | P1: RES+EXP | Q1: RES+EXP-GEN
A2: 44531 | B2: =A3-A2 -> 31 | C2: =(D2*D$1+E2*E$1+F2*F$1+G2*G$1+H2*H$1)/1000*B2 -> 3551.7074 | D2: 5733.3197 | E2: 5438.4765 | F2: 4562.1017 | G2: 4640.5107 | H2: 3066.9153 | I2: =AVERAGE(P_NOW_val_GMS!A1:AW1) -> 0 | J2: =AVERAGE(P_NOW_val_PCN!A1:AW1) -> 0.79177745 | K2: =AVERAGE(P_NOW_val_MCA!A1:AW1) -> 0 | L2: =AVERAGE(P_NOW_val_REV!A1:AW1) -> 107.00421 | M2: =AVERAGE(P_NOW_val_ARD!A1:AW1) -> 61.38744 | N2: =AVERAGE('SPOT_EXP_USH_NOW '!A1:AW1) -> -3382.524 | O2: =SUM(I2:M2) -> 169.18343 | P2: =C2+N2 -> 169.18343 | Q2: =C2+N2-O2 -> -7.9580786e-13
A3: 44562 | B3: =A4-A3 -> 31 | C3: =(D3*D$1+E3*E$1+F3*F$1+G3*G$1+H3*H$1)/1000*B3 -> 3924.0584 | D3: 6001.1638 | E3: 5460.8344 | F3: 4732.8247 | G3: 5816.6765 | H3: 4526.2691 | I3: =AVERAGE(P_NOW_val_GMS!A2:AW2) -> 2030.2673 | J3: =AVERAGE(P_NOW_val_PCN!A2:AW2) -> 486.01997 | K3: =AVERAGE(P_NOW_val_MCA!A2:AW2) -> 639.30432 | L3: =AVERAGE(P_NOW_val_REV!A2:AW2) -> 1671.6551 | M3: =AVERAGE(P_NOW_val_ARD!A2:AW2) -> 66.3648 | N3: =AVERAGE('SPOT_EXP_USH_NOW '!A2:AW2) -> 969.55307 | O3: =SUM(I3:M3) -> 4893.6115 | P3: =C3+N3 -> 4893.6115 | Q3: =C3+N3-O3 -> 0
A4: 44593 | B4: =A5-A4 -> 28 | C4: =(D4*D$1+E4*E$1+F4*F$1+G4*G$1+H4*H$1)/1000*B4 -> 3088.3445 | D4: 4946.0685 | E4: 4877.1711 | F4: 4977.0065 | G4: 3645.5563 | H4: 4726.7321 | I4: =AVERAGE(P_NOW_val_GMS!A3:AW3) -> 1660.2946 | J4: =AVERAGE(P_NOW_val_PCN!A3:AW3) -> 401.48431 | K4: =AVERAGE(P_NOW_val_MCA!A3:AW3) -> 500.7744 | L4: =AVERAGE(P_NOW_val_REV!A3:AW3) -> 1513.1015 | M4: =AVERAGE(P_NOW_val_ARD!A3:AW3) -> 54.69744 | N4: =AVERAGE('SPOT_EXP_USH_NOW '!A3:AW3) -> 1042.0077 | O4: =SUM(I4:M4) -> 4130.3522 | P4: =C4+N4 -> 4130.3522 | Q4: =C4+N4-O4 -> 9.094947e-12
A5: 44621 | B5: =A6-A5 -> 31 | C5: =(D5*D$1+E5*E$1+F5*F$1+G5*G$1+H5*H$1)/1000*B5 -> 3102.6643 | D5: 4427.8573 | E5: 4310.9967 | F5: 4222.2048 | G5: 4011.5879 | H5: 3758.5424 | I5: =AVERAGE(P_NOW_val_GMS!A4:AW4) -> 0 | J5: =AVERAGE(P_NOW_val_PCN!A4:AW4) -> 0.56691165 | K5: =AVERAGE(P_NOW_val_MCA!A4:AW4) -> 0 | L5: =AVERAGE(P_NOW_val_REV!A4:AW4) -> 53.215155 | M5: =AVERAGE(P_NOW_val_ARD!A4:AW4) -> 43.96668 | N5: =AVERAGE('SPOT_EXP_USH_NOW '!A4:AW4) -> -3004.9155 | O5: =SUM(I5:M5) -> 97.748747 | P5: =C5+N5 -> 97.748747 | Q5: =C5+N5-O5 -> 4.3485215e-12
A6: 44652 | B6: =A7-A6 -> 30 | C6: =(D6*D$1+E6*E$1+F6*F$1+G6*G$1+H6*H$1)/1000*B6 -> 2695.1637 | D6: 3823.6701 | E6: 3714.1835 | F6: 3545.4272 | G6: 4011.5644 | H6: 3736.773 | I6: =AVERAGE(P_NOW_val_GMS!A5:AW5) -> 1783.1521 | J6: =AVERAGE(P_NOW_val_PCN!A5:AW5) -> 444.62801 | K6: =AVERAGE(P_NOW_val_MCA!A5:AW5) -> 269.27723 | L6: =AVERAGE(P_NOW_val_REV!A5:AW5) -> 1062.8654 | M6: =AVERAGE(P_NOW_val_ARD!A5:AW5) -> 53.7876 | N6: =AVERAGE('SPOT_EXP_USH_NOW '!A5:AW5) -> 918.54664 | O6: =SUM(I6:M6) -> 3613.7104 | P6: =C6+N6 -> 3613.7104 | Q6: =C6+N6-O6 -> 0
A7: 44682 | B7: =A8-A7 -> 31 | C7: =(D7*D$1+E7*E$1+F7*F$1+G7*G$1+H7*H$1)/1000*B7 -> 1277.27 | D7: 2575.5495 | E7: 2102.7156 | F7: 1932.2334 | G7: 769.03948 | H7: 1681.3804 | I7: =AVERAGE(P_NOW_val_GMS!A6:AW6) -> 0 | J7: =AVERAGE(P_NOW_val_PCN!A6:AW6) -> 9.9671524 | K7: =AVERAGE(P_NOW_val_MCA!A6:AW6) -> 280.99872 | L7: =AVERAGE(P_NOW_val_REV!A6:AW6) -> 1277.6879 | M7: =AVERAGE(P_NOW_val_ARD!A6:AW6) -> 75.48996 | N7: =AVERAGE('SPOT_EXP_USH_NOW '!A6:AW6) -> 366.87378 | O7: =SUM(I7:M7) -> 1644.1438 | P7: =C7+N7 -> 1644.1438 | Q7: =C7+N7-O7 -> 0
A8: 44713 | B8: =A9-A8 -> 30 | C8: =(D8*D$1+E8*E$1+F8*F$1+G8*G$1+H8*H$1)/1000*B8 -> 1324.5083 | D8: 1689.9345 | E8: 1833.3639 | F8: 1637.8555 | G8: 2438.6405 | H8: 1017.7691 | I8: =AVERAGE(P_NOW_val_GMS!A7:AW7) -> 722.60637 | J8: =AVERAGE(P_NOW_val_PCN!A7:AW7) -> 143.75003 | K8: =AVERAGE(P_NOW_val_MCA!A7:AW7) -> 325.20502 | L8: =AVERAGE(P_NOW_val_REV!A7:AW7) -> 1273.1798 | M8: =AVERAGE(P_NOW_val_ARD!A7:AW7) -> 103.79916 | N8: =AVERAGE('SPOT_EXP_USH_NOW '!A7:AW7) -> 1244.0321 | O8: =SUM(I8:M8) -> 2568.5404 | P8: =C8+N8 -> 2568.5404 | Q8: =C8+N8-O8 -> 0
A9: 44743 | B9: =A10-A9 -> 31 | C9: =(D9*D$1+E9*E$1+F9*F$1+G9*G$1+H9*H$1)/1000*B9 -> 1365.0494 | D9: 2549.6282 | E9: 2291.3684 | F9: 1944.7731 | G9: 1197.4145 | H9: 1221.8558 | I9: =AVERAGE(P_NOW_val_GMS!A8:AW8) -> 1486.9631 | J9: =AVERAGE(P_NOW_val_PCN!A8:AW8) -> 334.0086 | K9: =AVERAGE(P_NOW_val_MCA!A8:AW8) -> 269.83447 | L9: =AVERAGE(P_NOW_val_REV!A8:AW8) -> 1020.2166 | M9: =AVERAGE(P_NOW_val_ARD!A8:AW8) -> 98.456654 | N9: =AVERAGE('SPOT_EXP_USH_NOW '!A8:AW8) -> 1844.4301 | O9: =SUM(I9:M9) -> 3209.4795 | P9: =C9+N9 -> 3209.4795 | Q9: =C9+N9-O9 -> 0
A10: 44774 | B10: =A11-A10 -> 31 | C10: =(D10*D$1+E10*E$1+F10*F$1+G10*G$1+H10*H$1)/1000*B10 -> 2061.4236 | D10: 2719.6827 | E10: 2799.9833 | F10: 2652.9269 | G10: 3239.9824 | H10: 1797.4799 | I10: =AVERAGE(P_NOW_val_GMS!A9:AW9) -> 1890.3812 | J10: =AVERAGE(P_NOW_val_PCN!A9:AW9) -> 501.09919 | K10: =AVERAGE(P_NOW_val_MCA!A9:AW9) -> 448.26952 | L10: =AVERAGE(P_NOW_val_REV!A9:AW9) -> 1137.5707 | M10: =AVERAGE(P_NOW_val_ARD!A9:AW9) -> 96.870887 | N10: =AVERAGE('SPOT_EXP_USH_NOW '!A9:AW9) -> 2012.768 | O10: =SUM(I10:M10) -> 4074.1916 | P10: =C10+N10 -> 4074.1916 | Q10: =C10+N10-O10 -> 4.5474735e-12
A11: 44805 | B11: =A12-A11 -> 30 | C11: =(D11*D$1+E11*E$1+F11*F$1+G11*G$1+H11*H$1)/1000*B11 -> 2069.8485 | D11: 3390.6282 | E11: 3231.7181 | F11: 3171.0725 | G11: 2110.9113 | H11: 2394.6687 | I11: =AVERAGE(P_NOW_val_GMS!A10:AW10) -> 1862.0494 | J11: =AVERAGE(P_NOW_val_PCN!A10:AW10) -> 367.32815 | K11: =AVERAGE(P_NOW_val_MCA!A10:AW10) -> 396.5219 | L11: =AVERAGE(P_NOW_val_REV!A10:AW10) -> 1158.3226 | M11: =AVERAGE(P_NOW_val_ARD!A10:AW10) -> 67.593674 | N11: =AVERAGE('SPOT_EXP_USH_NOW '!A10:AW10) -> 1781.9672 | O11: =SUM(I11:M11) -> 3851.8157 | P11: =C11+N11 -> 3851.8157 | Q11: =C11+N11-O11 -> 0
A12: 44835 | B12: =A13-A12 -> 31 | C12: =(D12*D$1+E12*E$1+F12*F$1+G12*G$1+H12*H$1)/1000*B12 -> 2455.0803 | D12: 3623.5377 | E12: 3487.7827 | F12: 3373.1287 | G12: 2937.2693 | H12: 3206.8609 | I12: =AVERAGE(P_NOW_val_GMS!A11:AW11) -> 1053.9463 | J12: =AVERAGE(P_NOW_val_PCN!A11:AW11) -> 245.82825 | K12: =AVERAGE(P_NOW_val_MCA!A11:AW11) -> 475.13932 | L12: =AVERAGE(P_NOW_val_REV!A11:AW11) -> 1103.4577 | M12: =AVERAGE(P_NOW_val_ARD!A11:AW11) -> 110.02674 | N12: =AVERAGE('SPOT_EXP_USH_NOW '!A11:AW11) -> 533.31806 | O12: =SUM(I12:M12) -> 2988.3984 | P12: =C12+N12 -> 2988.3984 | Q12: =C12+N12-O12 -> 0
A13: 44866 | B13: =A14-A13 -> 30 | C13: =(D13*D$1+E13*E$1+F13*F$1+G13*G$1+H13*H$1)/1000*B13 -> 3403.5116 | D13: 5159.8238 | E13: 4499.3434 | F13: 4320.3969 | G13: 5549.3779 | H13: 4137.618 | I13: =AVERAGE(P_NOW_val_GMS!A12:AW12) -> 644.26145 | J13: =AVERAGE(P_NOW_val_PCN!A12:AW12) -> 152.26701 | K13: =AVERAGE(P_NOW_val_MCA!A12:AW12) -> 219.76998 | L13: =AVERAGE(P_NOW_val_REV!A12:AW12) -> 542.08313 | M13: =AVERAGE(P_NOW_val_ARD!A12:AW12) -> 82.6884 | N13: =AVERAGE('SPOT_EXP_USH_NOW '!A12:AW12) -> -1762.4417 | O13: =SUM(I13:M13) -> 1641.07 | P13: =C13+N13 -> 1641.07 | Q13: =C13+N13-O13 -> 0
... A61: 46327 | B61: =A62-A61 -> 30 | C61: =(D61*D$1+E61*E$1+F61*F$1+G61*G$1+H61*H$1)/1000*B61 -> 3459.8973 | D61: 5337.8365 | E61: 5287.3393 | F61: 4740.4653 | G61: 4322.1863 | H61: 4536.6812 | I61: =AVERAGE(P_NOW_val_GMS!A60:AW60) -> 593.24554 | J61: =AVERAGE(P_NOW_val_PCN!A60:AW60) -> 138.95216 | K61: =AVERAGE(P_NOW_val_MCA!A60:AW60) -> 87.098056 | L61: =AVERAGE(P_NOW_val_REV!A60:AW60) -> 262.71522 | M61: =AVERAGE(P_NOW_val_ARD!A60:AW60) -> 82.601634 | N61: =AVERAGE('SPOT_EXP_USH_NOW '!A60:AW60) -> -2295.2847 | O61: =SUM(I61:M61) -> 1164.6126 | P61: =C61+N61 -> 1164.6126 | Q61: =C61+N61-O61 -> 1.8189894e-12
A62: 46357

Sheet P_NOW_val_GMS
A1: 0 | B1: 0 | C1: 0 | D1: 0 | E1: 0 | F1: 0 | G1: 0 | H1: 0 | I1: 0 | J1: 0 | K1: 0 | L1: 0 | M1: 0 | N1: 0 | O1: 0 | P1: 0 | Q1: 0 | R1: 0 | S1: 0 | T1: 0 | U1: 0 | V1: 0 | W1: 0 | X1: 0 | Y1: 0 | Z1: 0 | AA1: 0 | AB1: 0 | AC1: 0 | AD1: 0 | AE1: 0 | AF1: 0 | AG1: 0 | AH1: 0 | AI1: 0 | AJ1: 0 | AK1: 0 | AL1: 0 | AM1: 0 | AN1: 0 | AO1: 0 | AP1: 0 | AQ1: 0 | AR1: 0 | AS1: 0 | AT1: 0 | AU1: 0 | AV1: 0 | AW1: 0
A2: 2030.2673 | B2: 2030.2673 | C2: 2030.2673 | D2: 2030.2673 | E2: 2030.2673 | F2: 2030.2673 | G2: 2030.2673 | H2: 2030.2673 | I2: 2030.2673 | J2: 2030.2673 | K2: 2030.2673 | L2: 2030.2673 | M2: 2030.2673 | N2: 2030.2673 | O2: 2030.2673 | P2: 2030.2673 | Q2: 2030.2673 | R2: 2030.2673 | S2: 2030.2673 | T2: 2030.2673 | U2: 2030.2673 | V2: 2030.2673 | W2: 2030.2673 | X2: 2030.2673 | Y2: 2030.2673 | Z2: 2030.2673 | AA2: 2030.2673 | AB2: 2030.2673 | AC2: 2030.2673 | AD2: 2030.2673 | AE2: 2030.2673 | AF2: 2030.2673 | AG2: 2030.2673 | AH2: 2030.2673 | AI2: 2030.2673 | AJ2: 2030.2673 | AK2: 2030.2673 | AL2: 2030.2673 | AM2: 2030.2673 | AN2: 2030.2673 | AO2: 2030.2673 | AP2: 2030.2673 | AQ2: 2030.2673 | AR2: 2030.2673 | AS2: 2030.2673 | AT2: 2030.2673 | AU2: 2030.2673 | AV2: 2030.2673 | AW2: 2030.2673
A3: 1660.2946 | B3: 1660.2946 | C3: 1660.2946 | D3: 1660.2946 | E3: 1660.2946 | F3: 1660.2946 | G3: 1660.2946 | H3: 1660.2946 | I3: 1660.2946 | J3: 1660.2946 | K3: 1660.2946 | L3: 1660.2946 | M3: 1660.2946 | N3: 1660.2946 | O3: 1660.2946 | P3: 1660.2946 | Q3: 1660.2946 | R3: 1660.2946 | S3: 1660.2946 | T3: 1660.2946 | U3: 1660.2946 | V3: 1660.2946 | W3: 1660.2946 | X3: 1660.2946 | Y3: 1660.2946 | Z3: 1660.2946 | AA3: 1660.2946 | AB3: 1660.2946 | AC3: 1660.2946 | AD3: 1660.2946 | AE3: 1660.2946 | AF3: 1660.2946 | AG3: 1660.2946 | AH3: 1660.2946 | AI3: 1660.2946 | AJ3: 1660.2946 | AK3: 1660.2946 | AL3: 1660.2946 | AM3: 1660.2946 | AN3: 1660.2946 | AO3: 1660.2946 | AP3: 1660.2946 | AQ3: 1660.2946 | AR3: 1660.2946 | AS3: 1660.2946 | AT3: 1660.2946 | AU3: 1660.2946 | AV3: 1660.2946 | AW3: 1660.2946
A4: 0 | B4: 0 | C4: 0 | D4: 0 | E4: 0 | F4: 0 | G4: 0 | H4: 0 | I4: 0 | J4: 0 | K4: 0 | L4: 0 | M4: 0 | N4: 0 | O4: 0 | P4: 0 | Q4: 0 | R4: 0 | S4: 0 | T4: 0 | U4: 0 | V4: 0 | W4: 0 | X4: 0 | Y4: 0 | Z4: 0 | AA4: 0 | AB4: 0 | AC4: 0 | AD4: 0 | AE4: 0 | AF4: 0 | AG4: 0 | AH4: 0 | AI4: 0 | AJ4: 0 | AK4: 0 | AL4: 0 | AM4: 0 | AN4: 0 | AO4: 0 | AP4: 0 | AQ4: 0 | AR4: 0 | AS4: 0 | AT4: 0 | AU4: 0 | AV4: 0 | AW4: 0
A5: 1783.1521 | B5: 1783.1521 | C5: 1783.1521 | D5: 1783.1521 | E5: 1783.1521 | F5: 1783.1521 | G5: 1783.1521 | H5: 1783.1521 | I5: 1783.1521 | J5: 1783.1521 | K5: 1783.1521 | L5: 1783.1521 | M5: 1783.1521 | N5: 1783.1521 | O5: 1783.1521 | P5: 1783.1521 | Q5: 1783.1521 | R5: 1783.1521 | S5: 1783.1521 | T5: 1783.1521 | U5: 1783.1521 | V5: 1783.1521 | W5: 1783.1521 | X5: 1783.1521 | Y5: 1783.1521 | Z5: 1783.1521 | AA5: 1783.1521 | AB5: 1783.1521 | AC5: 1783.1521 | AD5: 1783.1521 | AE5: 1783.1521 | AF5: 1783.1521 | AG5: 1783.1521 | AH5: 1783.1521 | AI5: 1783.1521 | AJ5: 1783.1521 | AK5: 1783.1521 | AL5: 1783.1521 | AM5: 1783.1521 | AN5: 1783.1521 | AO5: 1783.1521 | AP5: 1783.1521 | AQ5: 1783.1521 | AR5: 1783.1521 | AS5: 1783.1521 | AT5: 1783.1521 | AU5: 1783.1521 | AV5: 1783.1521 | AW5: 1783.1521
A6: 0 | B6: 0 | C6: 0 | D6: 0 | E6: 0 | F6: 0 | G6: 0 | H6: 0 | I6: 0 | J6: 0 | K6: 0 | L6: 0 | M6: 0 | N6: 0 | O6: 0 | P6: 0 | Q6: 0 | R6: 0 | S6: 0 | T6: 0 | U6: 0 | V6: 0 | W6: 0 | X6: 0 | Y6: 0 | Z6: 0 | AA6: 0 | AB6: 0 | AC6: 0 | AD6: 0 | AE6: 0 | AF6: 0 | AG6: 0 | AH6: 0 | AI6: 0 | AJ6: 0 | AK6: 0 | AL6: 0 | AM6: 0 | AN6: 0 | AO6: 0 | AP6: 0 | AQ6: 0 | AR6: 0 | AS6: 0 | AT6: 0 | AU6: 0 | AV6: 0 | AW6: 0
A7: 803.35936 | B7: 0 | C7: 0 | D7: 932.95546 | E7: 120.08097 | F7: 0 | G7: 0 | H7: 0 | I7: 1805.4 | J7: 2.0868488 | K7: 0 | L7: 17.490209 | M7: 0 | N7: 0 | O7: 1276.896 | P7: 1805.4 | Q7: 0 | R7: 1805.4 | S7: 449.9993 | T7: 1805.4 | U7: 146.24302 | V7: 878.1652 | W7: 0 | X7: 1805.4 | Y7: 1805.4 | Z7: 371.66947 | AA7: 1526.2148 | AB7: 0 | AC7: 499.70415 | AD7: 1805.4 | AE7: 131.73448 | AF7: 0 | AG7: 1805.4 | AH7: 0 | AI7: 1805.4 | AJ7: 1522.9348 | AK7: 798.19869 | AL7: 0 | AM7: 1272.7295 | AN7: 1805.4 | AO7: 416.35112 | AP7: 296.07192 | AQ7: 1089.753 | AR7: 626.42061 | AS7: 563.85302 | AT7: 0 | AU7: 0 | AV7: 1805.4 | AW7: 1805.4
A8: 1939.9837 | B8: 1939.9837 | C8: 649.8654 | D8: 1939.9837 | E8: 1939.9837 | F8: 530.17159 | G8: 1939.9837 | H8: 651.395 | I8: 1555.7161 | J8: 1939.9837 | K8: 1337.4239 | L8: 1939.9837 | M8: 1566.4243 | N8: 1939.9837 | O8: 1939.9837 | P8: 1939.9837 | Q8: 923.47866 | R8: 1418.4573 | S8: 1255.0371 | T8: 1196.8708 | U8: 1389.6828 | V8: 1939.9837 | W8: 1255.9721 | X8: 1939.9837 | Y8: 1939.9837 | Z8: 741.31317 | AA8: 1939.9837 | AB8: 1500.9698 | AC8: 1939.9837 | AD8: 1939.9837 | AE8: 1939.9837 | AF8: 1193.8051 | AG8: 1304.639 | AH8: 723.55367 | AI8: 1939.9837 | AJ8: 1845.748 | AK8: 1591.6016 | AL8: 653.3822 | AM8: 1939.9837 | AN8: 1939.9837 | AO8: 1134.6503 | AP8: 914.51814 | AQ8: 706.47696 | AR8: 1417.4157 | AS8: 1284.1575 | AT8: 788.08756 | AU8: 650.73752 | AV8: 1939.9837 | AW8: 1939.9837
A9: 1890.3812 | B9: 1890.3812 | C9: 1890.3812 | D9: 1890.3812 | E9: 1890.3812 | F9: 1890.3812 | G9: 1890.3812 | H9: 1890.3812 | I9: 1890.3812 | J9: 1890.3812 | K9: 1890.3812 | L9: 1890.3812 | M9: 1890.3812 | N9: 1890.3812 | O9: 1890.3812 | P9: 1890.3812 | Q9: 1890.3812 | R9: 1890.3812 | S9: 1890.3812 | T9: 1890.3812 | U9: 1890.3812 | V9: 1890.3812 | W9: 1890.3812 | X9: 1890.3812 | Y9: 1890.3812 | Z9: 1890.3812 | AA9: 1890.3812 | AB9: 1890.3812 | AC9: 1890.3812 | AD9: 1890.3812 | AE9: 1890.3812 | AF9: 1890.3812 | AG9: 1890.3812 | AH9: 1890.3812 | AI9: 1890.3812 | AJ9: 1890.3812 | AK9: 1890.3812 | AL9: 1890.3812 | AM9: 1890.3812 | AN9: 1890.3812 | AO9: 1890.3812 | AP9: 1890.3812 | AQ9: 1890.3812 | AR9: 1890.3812 | AS9: 1890.3812 | AT9: 1890.3812 | AU9: 1890.3812 | AV9: 1890.3812 | AW9: 1890.3812
A10: 1911.6 | B10: 1911.6 | C10: 1911.6 | D10: 1911.6 | E10: 1911.6 | F10: 1911.6 | G10: 1911.6 | H10: 952.13405 | I10: 1911.6 | J10: 1911.6 | K10: 1911.6 | L10: 1680.8636 | M10: 1911.6 | N10: 1911.6 | O10: 1911.6 | P10: 1911.6 | Q10: 1911.6 | R10: 1911.6 | S10: 1911.6 | T10: 1911.6 | U10: 1911.6 | V10: 1911.6 | W10: 1911.6 | X10: 1911.6 | Y10: 1911.6 | Z10: 1911.6 | AA10: 1911.6 | AB10: 1911.6 | AC10: 1911.6 | AD10: 1911.6 | AE10: 1911.6 | AF10: 1911.6 | AG10: 1911.6 | AH10: 1911.6 | AI10: 1911.6 | AJ10: 1911.6 | AK10: 1911.6 | AL10: 1911.6 | AM10: 1680.8636 | AN10: 1911.6 | AO10: 1911.6 | AP10: 1911.6 | AQ10: 1911.6 | AR10: 904.55767 | AS10: 1911.6 | AT10: 1911.6 | AU10: 1911.6 | AV10: 1911.6 | AW10: 1911.6
A11: 642.88749 | B11: 1540.8461 | C11: 502.84055 | D11: 845.95294 | E11: 831.03224 | F11: 1492.7422 | G11: 898.20421 | H11: 1371.0205 | I11: 613.12991 | J11: 952.43167 | K11: 689.73483 | L11: 1440.4885 | M11: 766.53195 | N11: 1223.8933 | O11: 915.76018 | P11: 763.8064 | Q11: 754.37257 | R11: 440.36291 | S11: 1252.8415 | T11: 1521.1537 | U11: 1118.9212 | V11: 1495.6175 | W11: 1217.8378 | X11: 1939.9837 | Y11: 1271.5449 | Z11: 947.05767 | AA11: 566.82456 | AB11: 1939.9837 | AC11: 717.03841 | AD11: 949.7944 | AE11: 1203.719 | AF11: 1001.0357 | AG11: 952.02714 | AH11: 940.569 | AI11: 1220.6467 | AJ11: 596.50727 | AK11: 642.27399 | AL11: 1592.126 | AM11: 1065.5103 | AN11: 584.15009 | AO11: 896.74054 | AP11: 1458.6952 | AQ11: 1326.8818 | AR11: 1071.7904 | AS11: 1463.3265 | AT11: 849.44438 | AU11: 1578.4937 | AV11: 864.01378 | AW11: 710.78048
A12: 297.78217 | B12: 580.34491 | C12: 375.88058 | D12: 565.18104 | E12: 517.54714 | F12: 657.05857 | G12: 297.87406 | H12: 827.18837 | I12: 594.42427 | J12: 652.94492 | K12: 629.70869 | L12: 510.555 | M12: 401.21745 | N12: 582.83447 | O12: 746.40487 | P12: 579.73267 | Q12: 657.22098 | R12: 369.41948 | S12: 829.99206 | T12: 708.20671 | U12: 551.99921 | V12: 560.84622 | W12: 448.08098 | X12: 1954.08 | Y12: 780.93387 | Z12: 489.92693 | AA12: 526.13344 | AB12: 1954.08 | AC12: 759.29181 | AD12: 480.31061 | AE12: 626.70092 | AF12: 735.34503 | AG12: 629.28023 | AH12: 283.32564 | AI12: 722.07878 | AJ12: 622.82447 | AK12: 511.28691 | AL12: 500.42368 | AM12: 585.89139 | AN12: 411.85844 | AO12: 479.09895 | AP12: 733.99875 | AQ12: 634.13113 | AR12: 1080.6308 | AS12: 495.09196 | AT12: 355.73653 | AU12: 893.31659 | AV12: 894.46628 | AW12: 486.12314
... A84: 580.34491 | B84: 375.88058 | C84: 565.18104 | D84: 517.54714 | E84: 657.05857 | F84: 297.87406 | G84: 827.18837 | H84: 594.42427 | I84: 652.94492 | J84: 629.70869 | K84: 510.555 | L84: 401.21745 | M84: 582.83447 | N84: 746.40487 | O84: 579.73267 | P84: 657.22098 | Q84: 369.41948 | R84: 829.99206 | S84: 708.20671 | T84: 551.99921 | U84: 560.84622 | V84: 448.08098 | W84: 589.90353 | X84: 780.93387 | Y84: 489.92693 | Z84: 526.13344 | AA84: 818.47705 | AB84: 759.29181 | AC84: 480.31061 | AD84: 626.70092 | AE84: 735.34503 | AF84: 629.28023 | AG84: 283.32564 | AH84: 722.07878 | AI84: 622.82447 | AJ84: 511.28691 | AK84: 500.42368 | AL84: 585.89139 | AM84: 411.85844 | AN84: 479.09895 | AO84: 733.99875 | AP84: 634.13113 | AQ84: 1080.6308 | AR84: 495.09196 | AS84: 355.73653 | AT84: 893.31659 | AU84: 894.46628 | AV84: 486.12314 | AW84: 297.78217

Sheet P_NOW_val_PCN
A1: 0.79186078 | B1: 0.75715466 | C1: 0.69029436 | D1: 1.0975808 | E1: 1.0302101 | F1: 0.67141015 | G1: 1.0105603 | H1: 0.52467475 | I1: 1.2116516 | J1: 0.81457286 | K1: 0.8582107 | L1: 0.84162322 | M1: 0.84187841 | N1: 0.65482267 | O1: 0.77272138 | P1: 0.8804124 | Q1: 1.0802277 | R1: 2.6585903 | S1: 0.7719558 | T1: 0.91103544 | U1: 0.51906053 | V1: 0.83677457 | W1: 0.79645423 | X1: 0.74235353 | Y1: 0.73903603 | Z1: 0.87888125 | AA1: 0.42617064 | AB1: 0.40983835 | AC1: 0.6091433 | AD1: 0.56678143 | AE1: 0.82758766 | AF1: 0.60480504 | AG1: 0.81533844 | AH1: 0.71581356 | AI1: 0.25953026 | AJ1: 0.6282827 | AK1: 0.39912029 | AL1: 0.54509011 | AM1: 0.68697686 | AN1: 0.79186078 | AO1: 0.79186078 | AP1: 0.79186078 | AQ1: 0.79186078 | AR1: 0.79186078 | AS1: 0.79186078 | AT1: 0.79186078 | AU1: 0.79186078 | AV1: 0.79186078 | AW1: 0.79186078
A2: 486.198 | B2: 486.07752 | C2: 486.0752 | D2: 486.17869 | E2: 486.27394 | F2: 486.02321 | G2: 486.00596 | H2: 485.80053 | I2: 486.4997 | J2: 485.90891 | K2: 485.97584 | L2: 486.19671 | M2: 486.08499 | N2: 486.07031 | O2: 486.32001 | P2: 486.01806 | Q2: 486.29093 | R2: 486.41706 | S2: 486.00776 | T2: 486.27883 | U2: 485.84687 | V2: 485.97635 | W2: 486.11176 | X2: 486.03633 | Y2: 486.068 | Z2: 485.8237 | AA2: 485.76527 | AB2: 485.7838 | AC2: 485.85459 | AD2: 485.89243 | AE2: 485.92976 | AF2: 485.80182 | AG2: 485.99437 | AH2: 485.87647 | AI2: 485.73129 | AJ2: 485.8219 | AK2: 485.85382 | AL2: 485.88445 | AM2: 486.01986 | AN2: 486.01986 | AO2: 486.01986 | AP2: 486.01986 | AQ2: 486.01986 | AR2: 486.01986 | AS2: 486.01986 | AT2: 486.01986 | AU2: 486.02501 | AV2: 486.01986 | AW2: 486.01986
A3: 401.6538 | B3: 401.61462 | C3: 401.45995 | D3: 401.5079 | E3: 401.89398 | F3: 401.45534 | G3: 401.35346 | H3: 401.3265 | I3: 402.00277 | J3: 401.37651 | K3: 401.44612 | L3: 401.74854 | M3: 401.45488 | N3: 401.51827 | O3: 401.70474 | P3: 401.53187 | Q3: 401.59226 | R3: 401.57659 | S3: 401.5238 | T3: 401.67662 | U3: 401.39864 | V3: 401.41455 | W3: 401.59987 | X3: 401.49084 | Y3: 401.61185 | Z3: 401.33664 | AA3: 401.29261 | AB3: 401.29861 | AC3: 401.27832 | AD3: 401.34609 | AE3: 401.3265 | AF3: 401.33203 | AG3: 401.70912 | AH3: 401.359 | AI3: 401.2479 | AJ3: 401.26518 | AK3: 401.3341 | AL3: 401.3424 | AM3: 401.48439 | AN3: 401.48439 | AO3: 401.48439 | AP3: 401.48439 | AQ3: 401.48439 | AR3: 401.48439 | AS3: 401.48439 | AT3: 401.48439 | AU3: 401.48462 | AV3: 401.48439 | AW3: 401.48439
A4: 0.93620124 | B4: 0.74556612 | C4: 0.41234638 | D4: 0.48128839 | E4: 0.93254522 | F4: 0.44368366 | G4: 0.53638978 | H4: 0.29483158 | I4: 1.1965618 | J4: 0.3240797 | K4: 0.489645 | L4: 0.86778151 | M4: 0.52724974 | N4: 0.85185173 | O4: 0.55127498 | P4: 0.65129314 | Q4: 0.54683554 | R4: 0.79962293 | S4: 0.58444027 | T4: 2.0787062 | U4: 0.43663277 | V4: 0.73825409 | W4: 0.78160399 | X4: 0.51523711 | Y4: 0.74608841 | Z4: 0.34157635 | AA4: 0.26793374 | AB4: 0.22327812 | AC4: 0.24051362 | AD4: 0.3240797 | AE4: 0.24521422 | AF4: 0.36063986 | AG4: 0.79753378 | AH4: 0.28856412 | AI4: 0.24756451 | AJ4: 0.17444419 | AK4: 0.27158976 | AL4: 0.28934755 | AM4: 0.56694362 | AN4: 0.56694362 | AO4: 0.56694362 | AP4: 0.56694362 | AQ4: 0.56694362 | AR4: 0.56694362 | AS4: 0.56694362 | AT4: 0.56694362 | AU4: 0.56694362 | AV4: 0.56694362 | AW4: 0.56694362
A5: 445.12544 | B5: 445.53218 | C5: 443.65363 | D5: 444.49584 | E5: 446.05159 | F5: 444.23176 | G5: 444.22701 | H5: 444.18004 | I5: 444.69646 | J5: 443.47899 | K5: 444.98728 | L5: 444.51358 | M5: 444.10284 | N5: 444.42863 | O5: 445.16266 | P5: 445.19439 | Q5: 444.29272 | R5: 445.37753 | S5: 446.60349 | T5: 448.27542 | U5: 444.18279 | V5: 447.60485 | W5: 444.74768 | X5: 445.88545 | Y5: 445.75628 | Z5: 443.5497 | AA5: 444.19853 | AB5: 443.15395 | AC5: 443.30235 | AD5: 443.29961 | AE5: 443.33883 | AF5: 444.14606 | AG5: 446.17601 | AH5: 443.50398 | AI5: 443.35732 | AJ5: 443.17244 | AK5: 443.33958 | AL5: 444.53731 | AM5: 444.62801 | AN5: 444.62801 | AO5: 444.62801 | AP5: 444.62801 | AQ5: 444.62801 | AR5: 444.62801 | AS5: 444.62801 | AT5: 444.62801 | AU5: 444.62801 | AV5: 444.62801 | AW5: 444.62801
A6: 13.509265 | B6: 10.834621 | C6: 7.5903274 | D6: 13.604075 | E6: 11.453119 | F6: 7.0527197 | G6: 9.7919715 | H6: 7.2510069 | I6: 14.767009 | J6: 8.1770473 | K6: 8.8299505 | L6: 6.3223401 | M6: 9.5750375 | N6: 9.3108297 | O6: 12.829573 | P6: 9.8240126 | Q6: 10.887672 | R6: 12.024606 | S6: 13.633227 | T6: 8.0094881 | U6: 8.4562251 | V6: 12.444292 | W6: 12.389402 | X6: 7.4240814 | Y6: 15.089784 | Z6: 17.417229 | AA6: 7.4666278 | AB6: 2.2384125 | AC6: 5.6071932 | AD6: 7.1556715 | AE6: 6.1445383 | AF6: 8.0008212 | AG6: 15.538885 | AH6: 7.8970816 | AI6: 8.4173556 | AJ6: 14.916447 | AK6: 6.8391999 | AL6: 10.030704 | AM6: 9.967147 | AN6: 9.967147 | AO6: 9.967147 | AP6: 9.967147 | AQ6: 9.967147 | AR6: 9.967147 | AS6: 9.967147 | AT6: 9.967147 | AU6: 9.967147 | AV6: 9.967147 | AW6: 9.967147
A7: 174.51158 | B7: 14.098614 | C7: 12.909473 | D7: 203.9734 | E7: 38.900697 | F7: 7.6394419 | G7: 15.098435 | H7: 8.9520077 | I7: 319.158 | J7: 13.945888 | K7: 8.0041421 | L7: 15.435422 | M7: 9.53568 | N7: 13.016172 | O7: 251.49625 | P7: 319.158 | Q7: 9.9318067 | R7: 319.158 | S7: 109.34133 | T7: 319.158 | U7: 35.384409 | V7: 187.80391 | W7: 7.9988198 | X7: 319.158 | Y7: 319.158 | Z7: 85.496096 | AA7: 319.158 | AB7: 13.164941 | AC7: 124.34414 | AD7: 319.158 | AE7: 40.747825 | AF7: 8.9697485 | AG7: 319.158 | AH7: 6.8862182 | AI7: 319.158 | AJ7: 319.158 | AK7: 173.91154 | AL7: 8.0713037 | AM7: 256.62484 | AN7: 319.158 | AO7: 102.38082 | AP7: 75.94343 | AQ7: 233.9559 | AR7: 148.55413 | AS7: 134.80176 | AT7: 11.854656 | AU7: 11.854656 | AV7: 319.158 | AW7: 319.158
A8: 487.2084 | B8: 487.2084 | C8: 124.01705 | D8: 487.2084 | E8: 487.2084 | F8: 163.60795 | G8: 487.2084 | H8: 122.48746 | I8: 307.02578 | J8: 487.2084 | K8: 278.43314 | L8: 487.2084 | M8: 311.13195 | N8: 487.2084 | O8: 487.2084 | P8: 487.2084 | Q8: 207.80722 | R8: 239.99536 | S8: 261.13512 | T8: 249.84534 | U8: 235.97725 | V8: 296.23232 | W8: 260.84122 | X8: 487.2084 | Y8: 487.2084 | Z8: 174.81449 | AA8: 487.2084 | AB8: 303.87158 | AC8: 487.2084 | AD8: 487.2084 | AE8: 487.2084 | AF8: 252.03501 | AG8: 266.45045 | AH8: 113.87448 | AI8: 487.2084 | AJ8: 147.43441 | AK8: 316.65851 | AL8: 120.50026 | AM8: 487.2084 | AN8: 487.2084 | AO8: 244.46195 | AP8: 206.44147 | AQ8: 170.15656 | AR8: 240.20299 | AS8: 209.79158 | AT8: 186.66921 | AU8: 123.14494 | AV8: 487.2084 | AW8: 487.2084
A9: 475.80685 | B9: 486.43536 | C9: 519.06202 | D9: 486.43551 | E9: 475.80685 | F9: 519.06202 | G9: 519.06202 | H9: 519.06202 | I9: 519.06202 | J9: 486.43536 | K9: 486.43536 | L9: 486.43536 | M9: 486.43536 | N9: 519.06202 | O9: 486.43536 | P9: 486.43536 | Q9: 519.06202 | R9: 519.06202 | S9: 519.06202 | T9: 519.06202 | U9: 519.06202 | V9: 519.06202 | W9: 486.43536 | X9: 486.43536 | Y9: 486.43536 | Z9: 519.06202 | AA9: 486.43536 | AB9: 475.80685 | AC9: 486.43536 | AD9: 486.43536 | AE9: 486.43536 | AF9: 519.06202 | AG9: 486.43536 | AH9: 519.06202 | AI9: 486.43536 | AJ9: 486.43536 | AK9: 486.43536 | AL9: 519.06202 | AM9: 486.43536 | AN9: 519.06202 | AO9: 486.43536 | AP9: 519.06202 | AQ9: 519.06202 | AR9: 519.06202 | AS9: 519.06202 | AT9: 519.06202 | AU9: 519.06202 | AV9: 486.43551 | AW9: 486.43536
A10: 330.94994 | B10: 333.11384 | C10: 332.44457 | D10: 333.25101 | E10: 331.46885 | F10: 492.3288 | G10: 316.11241 | H10: 221.35476 | I10: 332.94944 | J10: 332.25855 | K10: 330.09631 | L10: 440.3385 | M10: 331.9855 | N10: 492.3288 | O10: 333.14099 | P10: 333.34066 | Q10: 332.87192 | R10: 333.67424 | S10: 333.66333 | T10: 332.98403 | U10: 492.3288 | V10: 492.3288 | W10: 492.3288 | X10: 316.55324 | Y10: 332.84613 | Z10: 330.88847 | AA10: 334.06396 | AB10: 328.2192 | AC10: 332.89713 | AD10: 333.47988 | AE10: 333.18464 | AF10: 332.42728 | AG10: 331.64351 | AH10: 492.3288 | AI10: 333.14237 | AJ10: 333.42178 | AK10: 333.17294 | AL10: 492.3288 | AM10: 440.90803 | AN10: 331.72794 | AO10: 333.05124 | AP10: 492.3288 | AQ10: 332.91896 | AR10: 209.10872 | AS10: 492.3288 | AT10: 492.3288 | AU10: 492.3288 | AV10: 331.36782 | AW10: 332.44053
A11: 151.37911 | B11: 361.34432 | C11: 117.60689 | D11: 198.39753 | E11: 195.78226 | F11: 348.37736 | G11: 209.58766 | H11: 320.32726 | I11: 143.31608 | J11: 223.39005 | K11: 162.12733 | L11: 339.16141 | M11: 180.05957 | N11: 285.33973 | O11: 213.37145 | P11: 178.66378 | Q11: 176.68051 | R11: 103.0418 | S11: 293.41979 | T11: 356.92133 | U11: 260.65642 | V11: 348.41853 | W11: 283.79122 | X11: 436.821 | Y11: 300.54376 | Z11: 220.63238 | AA11: 131.99049 | AB11: 436.821 | AC11: 166.99358 | AD11: 221.44614 | AE11: 280.73725 | AF11: 235.35437 | AG11: 223.24506 | AH11: 218.20521 | AI11: 286.44833 | AJ11: 138.97102 | AK11: 149.84687 | AL11: 371.26182 | AM11: 249.13938 | AN11: 137.6125 | AO11: 210.03692 | AP11: 340.23681 | AQ11: 309.69681 | AR11: 250.59441 | AS11: 341.30984 | AT11: 199.07883 | AU11: 367.99305 | AV11: 202.45443 | AW11: 166.95164
A12: 70.197961 | B12: 135.50201 | C12: 88.685787 | D12: 132.55883 | E12: 121.46524 | F12: 156.20657 | G12: 69.961922 | H12: 193.81728 | I12: 139.9179 | J12: 153.03974 | K12: 147.98186 | L12: 120.14288 | M12: 94.150598 | N12: 136.12319 | O12: 175.68289 | P12: 135.69842 | Q12: 155.55369 | R12: 86.517348 | S12: 193.48291 | T12: 165.43241 | U12: 129.69317 | V12: 131.28229 | W12: 104.73867 | X12: 490.90176 | Y12: 183.63144 | Z12: 114.37169 | AA12: 122.53572 | AB12: 490.90176 | AC12: 176.65702 | AD12: 112.09625 | AE12: 146.40736 | AF12: 171.89586 | AG12: 147.46818 | AH12: 65.919289 | AI12: 168.83182 | AJ12: 144.85565 | AK12: 119.27749 | AL12: 117.40973 | AM12: 137.24741 | AN12: 96.905543 | AO12: 112.49229 | AP12: 171.57958 | AQ12: 148.42967 | AR12: 251.93093 | AS12: 116.19957 | AT12: 83.896151 | AU12: 208.5104 | AV12: 208.7769 | AW12: 114.12054
... A84: 135.50201 | B84: 88.685787 | C84: 132.55883 | D84: 121.46524 | E84: 156.20657 | F84: 69.961922 | G84: 193.81728 | H84: 139.9179 | I84: 153.03974 | J84: 147.98186 | K84: 120.14288 | L84: 94.150598 | M84: 136.12319 | N84: 175.68289 | O84: 135.69842 | P84: 155.55369 | Q84: 86.517348 | R84: 193.48291 | S84: 165.43241 | T84: 129.69317 | U84: 131.28229 | V84: 104.73867 | W84: 137.83887 | X84: 183.63144 | Y84: 114.37169 | Z84: 122.53572 | AA84: 191.53714 | AB84: 176.65702 | AC84: 112.09625 | AD84: 146.40736 | AE84: 171.89586 | AF84: 147.46818 | AG84: 65.919289 | AH84: 168.83182 | AI84: 144.85565 | AJ84: 119.27749 | AK84: 117.40973 | AL84: 137.24741 | AM84: 96.905543 | AN84: 112.49229 | AO84: 171.57958 | AP84: 148.42967 | AQ84: 251.93093 | AR84: 116.19957 | AS84: 83.896151 | AT84: 208.5104 | AU84: 208.7769 | AV84: 114.12054 | AW84: 70.197961

Sheet P_NOW_val_MCA
A1: 0 | B1: 0 | C1: 0 | D1: 0 | E1: 0 | F1: 0 | G1: 0 | H1: 0 | I1: 0 | J1: 0 | K1: 0 | L1: 0 | M1: 0 | N1: 0 | O1: 0 | P1: 0 | Q1: 0 | R1: 0 | S1: 0 | T1: 0 | U1: 0 | V1: 0 | W1: 0 | X1: 0 | Y1: 0 | Z1: 0 | AA1: 0 | AB1: 0 | AC1: 0 | AD1: 0 | AE1: 0 | AF1: 0 | AG1: 0 | AH1: 0 | AI1: 0 | AJ1: 0 | AK1: 0 | AL1: 0 | AM1: 0 | AN1: 0 | AO1: 0 | AP1: 0 | AQ1: 0 | AR1: 0 | AS1: 0 | AT1: 0 | AU1: 0 | AV1: 0 | AW1: 0
A2: 639.30432 | B2: 639.30432 | C2: 639.30432 | D2: 639.30432 | E2: 639.30432 | F2: 639.30432 | G2: 639.30432 | H2: 639.30432 | I2: 639.30432 | J2: 639.30432 | K2: 639.30432 | L2: 639.30432 | M2: 639.30432 | N2: 639.30432 | O2: 639.30432 | P2: 639.30432 | Q2: 639.30432 | R2: 639.30432 | S2: 639.30432 | T2: 639.30432 | U2: 639.30432 | V2: 639.30432 | W2: 639.30432 | X2: 639.30432 | Y2: 639.30432 | Z2: 639.30432 | AA2: 639.30432 | AB2: 639.30432 | AC2: 639.30432 | AD2: 639.30432 | AE2: 639.30432 | AF2: 639.30432 | AG2: 639.30432 | AH2: 639.30432 | AI2: 639.30432 | AJ2: 639.30432 | AK2: 639.30432 | AL2: 639.30432 | AM2: 639.30432 | AN2: 639.30432 | AO2: 639.30432 | AP2: 639.30432 | AQ2: 639.30432 | AR2: 639.30432 | AS2: 639.30432 | AT2: 639.30432 | AU2: 639.30432 | AV2: 639.30432 | AW2: 639.30432
A3: 500.7744 | B3: 500.7744 | C3: 500.7744 | D3: 500.7744 | E3: 500.7744 | F3: 500.7744 | G3: 500.7744 | H3: 500.7744 | I3: 500.7744 | J3: 500.7744 | K3: 500.7744 | L3: 500.7744 | M3: 500.7744 | N3: 500.7744 | O3: 500.7744 | P3: 500.7744 | Q3: 500.7744 | R3: 500.7744 | S3: 500.7744 | T3: 500.7744 | U3: 500.7744 | V3: 500.7744 | W3: 500.7744 | X3: 500.7744 | Y3: 500.7744 | Z3: 500.7744 | AA3: 500.7744 | AB3: 500.7744 | AC3: 500.7744 | AD3: 500.7744 | AE3: 500.7744 | AF3: 500.7744 | AG3: 500.7744 | AH3: 500.7744 | AI3: 500.7744 | AJ3: 500.7744 | AK3: 500.7744 | AL3: 500.7744 | AM3: 500.7744 | AN3: 500.7744 | AO3: 500.7744 | AP3: 500.7744 | AQ3: 500.7744 | AR3: 500.7744 | AS3: 500.7744 | AT3: 500.7744 | AU3: 500.7744 | AV3: 500.7744 | AW3: 500.7744
A4: 0 | B4: 0 | C4: 0 | D4: 0 | E4: 0 | F4: 0 | G4: 0 | H4: 0 | I4: 0 | J4: 0 | K4: 0 | L4: 0 | M4: 0 | N4: 0 | O4: 0 | P4: 0 | Q4: 0 | R4: 0 | S4: 0 | T4: 0 | U4: 0 | V4: 0 | W4: 0 | X4: 0 | Y4: 0 | Z4: 0 | AA4: 0 | AB4: 0 | AC4: 0 | AD4: 0 | AE4: 0 | AF4: 0 | AG4: 0 | AH4: 0 | AI4: 0 | AJ4: 0 | AK4: 0 | AL4: 0 | AM4: 0 | AN4: 0 | AO4: 0 | AP4: 0 | AQ4: 0 | AR4: 0 | AS4: 0 | AT4: 0 | AU4: 0 | AV4: 0 | AW4: 0
A5: 260.03947 | B5: 253.03987 | C5: 278.24613 | D5: 227.44859 | E5: 251.88288 | F5: 251.00835 | G5: 276.52657 | H5: 239.03361 | I5: 266.74881 | J5: 282.7106 | K5: 229.30354 | L5: 276.53641 | M5: 282.89591 | N5: 241.70905 | O5: 293.04599 | P5: 292.11223 | Q5: 298.70597 | R5: 277.82881 | S5: 273.96596 | T5: 280.29681 | U5: 285.18304 | V5: 277.35006 | W5: 309.36267 | X5: 270.97237 | Y5: 258.78647 | Z5: 259.74949 | AA5: 295.08546 | AB5: 265.82545 | AC5: 254.98448 | AD5: 250.46568 | AE5: 255.84479 | AF5: 302.66858 | AG5: 280.03684 | AH5: 283.41583 | AI5: 289.05219 | AJ5: 298.01511 | AK5: 232.03595 | AL5: 235.14965 | AM5: 265.66365 | AN5: 244.58009 | AO5: 275.04019 | AP5: 267.44135 | AQ5: 256.36422 | AR5: 303.7722 | AS5: 307.67121 | AT5: 278.99589 | AU5: 248.30448 | AV5: 262.10499 | AW5: 247.57654
A6: 235.85823 | B6: 243.44285 | C6: 219.82494 | D6: 243.19565 | E6: 250.77162 | F6: 251.72301 | G6: 209.22098 | H6: 229.35111 | I6: 379.44 | J6: 293.16399 | K6: 231.23325 | L6: 322.9425 | M6: 183.49942 | N6: 306.12494 | O6: 254.33277 | P6: 358.03233 | Q6: 295.66997 | R6: 293.66815 | S6: 261.03463 | T6: 274.65402 | U6: 278.66353 | V6: 379.44 | W6: 351.28248 | X6: 308.96125 | Y6: 191.53517 | Z6: 271.71447 | AA6: 379.44 | AB6: 230.92523 | AC6: 223.26808 | AD6: 310.19192 | AE6: 245.53004 | AF6: 243.35887 | AG6: 259.9323 | AH6: 324.85002 | AI6: 379.44 | AJ6: 269.13065 | AK6: 268.90773 | AL6: 230.59908 | AM6: 220.78079 | AN6: 239.99273 | AO6: 219.03871 | AP6: 346.48368 | AQ6: 283.40122 | AR6: 362.11243 | AS6: 352.00175 | AT6: 325.79779 | AU6: 379.44 | AV6: 314.68717 | AW6: 240.84563
A7: 366.73408 | B7: 505.70245 | C7: 505.70245 | D7: 227.7228 | E7: 490.53958 | F7: 505.70245 | G7: 505.70245 | H7: 505.70245 | I7: 24.749332 | J7: 498.34215 | K7: 505.70245 | L7: 505.70245 | M7: 505.70245 | N7: 505.70245 | O7: 95.518027 | P7: 4.5930158 | Q7: 505.70245 | R7: 21.87184 | S7: 478.93744 | T7: 30.940379 | U7: 504.25046 | V7: 300.29951 | W7: 505.70245 | X7: 17.591 | Y7: 26.525905 | Z7: 485.46492 | AA7: 89.95993 | AB7: 505.70245 | AC7: 474.79537 | AD7: 27.744238 | AE7: 505.4595 | AF7: 505.70245 | AG7: 21.286102 | AH7: 505.70245 | AI7: 26.217447 | AJ7: 52.705875 | AK7: 370.76657 | AL7: 505.70245 | AM7: 106.21319 | AN7: 7.2338731 | AO7: 481.74145 | AP7: 491.76472 | AQ7: 141.90378 | AR7: 464.12468 | AS7: 469.44963 | AT7: 505.70245 | AU7: 505.70245 | AV7: 21.38868 | AW7: 11.26861
A8: 130.79063 | B8: 159.91041 | C8: 533.1132 | D8: 129.30291 | E8: 138.45627 | F8: 651.92892 | G8: 189.23318 | H8: 533.1132 | I8: 211.76888 | J8: 132.01521 | K8: 237.29751 | L8: 169.57494 | M8: 162.98958 | N8: 156.18543 | O8: 182.08325 | P8: 147.09771 | Q8: 384.22391 | R8: 358.6553 | S8: 280.07218 | T8: 313.17533 | U8: 365.98826 | V8: 100.88003 | W8: 289.39032 | X8: 182.06452 | Y8: 157.48605 | Z8: 492.83574 | AA8: 178.59002 | AB8: 144.22904 | AC8: 164.21997 | AD8: 160.40569 | AE8: 134.24377 | AF8: 303.40663 | AG8: 295.08348 | AH8: 651.5828 | AI8: 177.90593 | AJ8: 124.24634 | AK8: 167.43048 | AL8: 533.1132 | AM8: 175.45301 | AN8: 128.69847 | AO8: 273.58396 | AP8: 402.84366 | AQ8: 532.32988 | AR8: 352.80049 | AS8: 276.73809 | AT8: 434.20664 | AU8: 533.1132 | AV8: 161.52225 | AW8: 126.50908
A9: 396.02163 | B9: 457.69746 | C9: 384.43465 | D9: 447.97248 | E9: 411.40576 | F9: 456.11031 | G9: 442.29294 | H9: 464.15404 | I9: 469.10457 | J9: 430.98156 | K9: 437.16675 | L9: 462.99215 | M9: 444.13687 | N9: 466.52075 | O9: 467.35727 | P9: 470.17132 | Q9: 431.84522 | R9: 461.6403 | S9: 458.59512 | T9: 448.44055 | U9: 435.09117 | V9: 425.57377 | W9: 462.17442 | X9: 455.20639 | Y9: 455.08322 | Z9: 439.77204 | AA9: 475.11202 | AB9: 366.58909 | AC9: 453.43761 | AD9: 469.21432 | AE9: 453.70572 | AF9: 429.90742 | AG9: 459.82112 | AH9: 480.28414 | AI9: 476.61537 | AJ9: 452.28676 | AK9: 447.11226 | AL9: 461.28123 | AM9: 481.20416 | AN9: 408.99796 | AO9: 435.58735 | AP9: 458.03058 | AQ9: 423.3405 | AR9: 478.00182 | AS9: 466.93677 | AT9: 463.01452 | AU9: 428.49764 | AV9: 472.33748 | AW9: 441.94789
A10: 369.2289 | B10: 393.03186 | C10: 385.66979 | D10: 394.5407 | E10: 374.93696 | F10: 269.68832 | G10: 358.92114 | H10: 586.3498 | I10: 391.22338 | J10: 383.62362 | K10: 359.839 | L10: 506.09936 | M10: 380.62003 | N10: 563.57387 | O10: 393.33044 | P10: 395.52683 | Q10: 390.37072 | R10: 399.19617 | S10: 399.07626 | T10: 391.60385 | U10: 368.13657 | V10: 360.1562 | W10: 342.96144 | X10: 351.8433 | Y10: 390.08703 | Z10: 368.55278 | AA10: 403.48313 | AB10: 372.89882 | AC10: 390.64803 | AD10: 397.05827 | AE10: 393.81061 | AF10: 385.47969 | AG10: 376.85817 | AH10: 237.71724 | AI10: 393.34559 | AJ10: 396.41911 | AK10: 393.68193 | AL10: 352.6722 | AM10: 512.36416 | AN10: 377.78687 | AO10: 392.34325 | AP10: 551.4613 | AQ10: 390.88811 | AR10: 591.41305 | AS10: 241.17702 | AT10: 563.56517 | AU10: 286.86191 | AV10: 373.8256 | AW10: 385.62539
A11: 645.68141 | B11: 571.78641 | C11: 483.78828 | D11: 645.68141 | E11: 645.68141 | F11: 169.02424 | G11: 264.01263 | H11: 145.31247 | I11: 645.68141 | J11: 581.92248 | K11: 645.68141 | L11: 625.6655 | M11: 645.68141 | N11: 205.60601 | O11: 645.68141 | P11: 645.68141 | Q11: 450.41857 | R11: 645.68141 | S11: 586.32605 | T11: 645.68141 | U11: 106.48459 | V11: 103.85888 | W11: 168.53614 | X11: 520.50813 | Y11: 645.68141 | Z11: 495.03633 | AA11: 645.68141 | AB11: 520.50813 | AC11: 423.47877 | AD11: 645.68141 | AE11: 645.68141 | AF11: 610.1357 | AG11: 645.68141 | AH11: 79.326098 | AI11: 645.68141 | AJ11: 645.68141 | AK11: 632.53413 | AL11: 162.38516 | AM11: 438.9198 | AN11: 645.68141 | AO11: 645.68141 | AP11: 264.89955 | AQ11: 575.24824 | AR11: 159.49011 | AS11: 114.47135 | AT11: 141.12476 | AU11: 121.70855 | AV11: 645.68141 | AW11: 645.68141
A12: 621.51415 | B12: 89.801208 | C12: 151.79454 | D12: 428.7976 | E12: 137.83827 | F12: 92.398597 | G12: 48.862447 | H12: 85.141501 | I12: 155.71055 | J12: 70.269595 | K12: 418.29607 | L12: 70.883064 | M12: 257.25965 | N12: 62.048171 | O12: 192.40575 | P12: 492.96265 | Q12: 100.55233 | R12: 372.6732 | S12: 77.543399 | T12: 180.20374 | U12: 68.11817 | V12: 44.420796 | W12: 98.117737 | X12: 446.0225 | Y12: 621.51415 | Z12: 73.362215 | AA12: 145.7511 | AB12: 434.33414 | AC12: 89.916019 | AD12: 180.06869 | AE12: 280.88763 | AF12: 99.862182 | AG12: 413.81731 | AH12: 73.869012 | AI12: 384.98411 | AJ12: 621.51415 | AK12: 67.7219 | AL12: 81.291899 | AM12: 86.11911 | AN12: 621.51415 | AO12: 151.11268 | AP12: 116.82211 | AQ12: 97.872692 | AR12: 135.85506 | AS12: 77.557108 | AT12: 75.374838 | AU12: 77.480424 | AV12: 374.97626 | AW12: 621.51415
... A84: 528.70814 | B84: 151.79454 | C84: 621.51415 | D84: 90.911839 | E84: 301.02421 | F84: 217.95558 | G84: 85.141501 | H84: 467.11453 | I84: 574.21127 | J84: 209.02568 | K84: 270.67798 | L84: 58.733212 | M84: 206.67188 | N84: 214.32446 | O84: 369.58718 | P84: 100.55233 | Q84: 459.66656 | R84: 530.46368 | S84: 238.61446 | T84: 68.11817 | U84: 108.67165 | V84: 209.26039 | W84: 621.51415 | X84: 621.51415 | Y84: 73.362215 | Z84: 621.51415 | AA84: 207.9554 | AB84: 89.916019 | AC84: 507.04963 | AD84: 266.97533 | AE84: 172.80885 | AF84: 237.25409 | AG84: 73.869012 | AH84: 514.36448 | AI84: 391.71069 | AJ84: 67.7219 | AK84: 81.291899 | AL84: 467.1996 | AM84: 621.51415 | AN84: 331.49578 | AO84: 315.83193 | AP84: 228.04987 | AQ84: 135.85506 | AR84: 158.31721 | AS84: 75.374838 | AT84: 77.480424 | AU84: 621.51415 | AV84: 621.51415 | AW84: 239.11192

Sheet P_NOW_val_REV
A1: 105.42298 | B1: 107.74522 | C1: 109.83295 | D1: 100.31741 | E1: 107.42078 | F1: 101.46442 | G1: 107.73993 | H1: 108.43731 | I1: 107.08928 | J1: 121.64781 | K1: 102.19177 | L1: 103.60504 | M1: 103.54068 | N1: 115.33085 | O1: 111.61386 | P1: 109.11529 | Q1: 102.7666 | R1: 104.0873 | S1: 107.43753 | T1: 102.00046 | U1: 116.28126 | V1: 105.31542 | W1: 109.17789 | X1: 110.61584 | Y1: 106.18296 | Z1: 107.14835 | AA1: 99.785778 | AB1: 110.99407 | AC1: 104.72296 | AD1: 102.48448 | AE1: 101.31102 | AF1: 108.28038 | AG1: 104.98481 | AH1: 110.46068 | AI1: 111.30617 | AJ1: 108.52459 | AK1: 105.59138 | AL1: 104.35444 | AM1: 107.03462 | AN1: 109.27663 | AO1: 114.3875 | AP1: 106.7234 | AQ1: 109.23167 | AR1: 103.20478 | AS1: 100.53341 | AT1: 106.15651 | AU1: 107.2709 | AV1: 107.42078 | AW1: 105.63634
A2: 1659.4474 | B2: 1682.2178 | C2: 1669.6862 | D2: 1662.6335 | E2: 1673.1417 | F2: 1664.1034 | G2: 1675.6158 | H2: 1664.253 | I2: 1667.881 | J2: 1676.8568 | K2: 1671.443 | L2: 1667.7807 | M2: 1701.9235 | N2: 1673.1557 | O2: 1677.4034 | P2: 1666.1471 | Q2: 1666.706 | R2: 1661.5157 | S2: 1674.0209 | T2: 1669.0798 | U2: 1680.1547 | V2: 1661.6777 | W2: 1670.7212 | X2: 1675.7548 | Y2: 1665.2555 | Z2: 1674.505 | AA2: 1669.0762 | AB2: 1677.4192 | AC2: 1669.651 | AD2: 1666.8195 | AE2: 1678.9084 | AF2: 1674.1134 | AG2: 1674.006 | AH2: 1688.3604 | AI2: 1687.0032 | AJ2: 1665.4254 | AK2: 1666.6268 | AL2: 1674.7911 | AM2: 1672.023 | AN2: 1669.1035 | AO2: 1670.3137 | AP2: 1670.3595 | AQ2: 1666.5502 | AR2: 1675.6879 | AS2: 1669.8913 | AT2: 1667.1276 | AU2: 1669.0886 | AV2: 1667.5976 | AW2: 1668.0738
A3: 1505.6918 | B3: 1514.3148 | C3: 1515.9827 | D3: 1506.3073 | E3: 1509.8552 | F3: 1509.215 | G3: 1512.3307 | H3: 1502.6161 | I3: 1505.0171 | J3: 1529.3318 | K3: 1508.3394 | L3: 1521.4083 | M3: 1517.0152 | N3: 1509.8352 | O3: 1517.9972 | P3: 1511.7193 | Q3: 1513.9418 | R3: 1506.0344 | S3: 1508.9068 | T3: 1541.9526 | U3: 1529.9937 | V3: 1502.4392 | W3: 1512.9358 | X3: 1515.3881 | Y3: 1512.0218 | Z3: 1517.9004 | AA3: 1523.8214 | AB3: 1516.4293 | AC3: 1504.8642 | AD3: 1508.6147 | AE3: 1513.3408 | AF3: 1512.0218 | AG3: 1505.258 | AH3: 1521.975 | AI3: 1514.9215 | AJ3: 1506.5778 | AK3: 1507.126 | AL3: 1505.3317 | AM3: 1515.4481 | AN3: 1508.1473 | AO3: 1506.9556 | AP3: 1516.9143 | AQ3: 1506.1792 | AR3: 1538.5951 | AS3: 1519.5955 | AT3: 1511.6856 | AU3: 1506.1688 | AV3: 1506.0736 | AW3: 1507.435
A4: 66.786252 | B4: 52.775997 | C4: 48.993909 | D4: 28.18491 | E4: 55.338342 | F4: 38.961078 | G4: 70.895373 | H4: 31.396017 | I4: 38.236303 | J4: 41.228209 | K4: 35.889623 | L4: 51.498802 | M4: 63.115532 | N4: 39.721208 | O4: 92.668676 | P4: 76.447857 | Q4: 69.060455 | R4: 65.113966 | S4: 57.645248 | T4: 45.801363 | U4: 57.391577 | V4: 40.347873 | W4: 63.435493 | X4: 46.854939 | Y4: 44.978478 | Z4: 53.535243 | AA4: 62.246686 | AB4: 49.512742 | AC4: 50.673266 | AD4: 55.941143 | AE4: 33.923891 | AF4: 54.723167 | AG4: 60.523135 | AH4: 53.740301 | AI4: 41.230861 | AJ4: 109.09102 | AK4: 39.744188 | AL4: 37.557489 | AM4: 54.460657 | AN4: 47.265939 | AO4: 43.019818 | AP4: 54.754103 | AQ4: 44.73453 | AR4: 97.711166 | AS4: 68.588467 | AT4: 55.145658 | AU4: 40.721751 | AV4: 38.996433 | AW4: 36.933475
A5: 1013.3172 | B5: 971.49387 | C5: 1120.1551 | D5: 854.59613 | E5: 980.1755 | F5: 974.99592 | G5: 1120.1749 | H5: 937.97736 | I5: 1063.7439 | J5: 1093.6691 | K5: 851.85962 | L5: 1066.3682 | M5: 1110.6793 | N5: 980.99064 | O5: 1155.8249 | P5: 1207.9468 | Q5: 1191.2184 | R5: 1087.8471 | S5: 1085.6686 | T5: 1108.185 | U5: 1142.67 | V5: 1143.4836 | W5: 1232.0287 | X5: 1048.3743 | Y5: 1055.0308 | Z5: 1000.5465 | AA5: 1201.9267 | AB5: 1043.0759 | AC5: 978.89129 | AD5: 990.12405 | AE5: 1025.0586 | AF5: 1264.5417 | AG5: 1115.0337 | AH5: 1103.9637 | AI5: 1160.5055 | AJ5: 1179.7223 | AK5: 889.22034 | AL5: 894.29734 | AM5: 1040.0838 | AN5: 936.01052 | AO5: 1093.2325 | AP5: 1044.8361 | AQ5: 1010.886 | AR5: 1188.0343 | AS5: 1229.3594 | AT5: 1124.425 | AU5: 959.33096 | AV5: 1047.6476 | AW5: 961.17579
A6: 1113.9551 | B6: 1178.325 | C6: 1034.1108 | D6: 1134.0346 | E6: 1168.9709 | F6: 1154.378 | G6: 970.85623 | H6: 1106.5545 | I6: 1560.4299 | J6: 1328.4062 | K6: 1036.9689 | L6: 1473.4322 | M6: 960.52175 | N6: 1424.3487 | O6: 1205.2439 | P6: 1560.4299 | Q6: 1345.7653 | R6: 1304.7539 | S6: 1181.9066 | T6: 1294.3488 | U6: 1375.0596 | V6: 1560.4299 | W6: 1560.4299 | X6: 1418.8858 | Y6: 904.95185 | Z6: 1263.8968 | AA6: 1560.4299 | AB6: 1101.4994 | AC6: 1057.2743 | AD6: 1386.7626 | AE6: 1168.8341 | AF6: 1236.6285 | AG6: 1227.6088 | AH6: 1526.4873 | AI6: 1560.4299 | AJ6: 1144.8059 | AK6: 1187.0562 | AL6: 1069.8103 | AM6: 1030.0845 | AN6: 1139.9113 | AO6: 1013.8239 | AP6: 1550.8702 | AQ6: 1268.7535 | AR6: 1560.4299 | AS6: 1536.8235 | AT6: 1532.6331 | AU6: 1560.4299 | AV6: 1444.0382 | AW6: 1119.8882
A7: 1502.7588 | B7: 1502.7588 | C7: 1502.7588 | D7: 1502.7588 | E7: 1502.7588 | F7: 1502.7588 | G7: 1502.7588 | H7: 1502.7588 | I7: 707.31421 | J7: 1502.7588 | K7: 1502.7588 | L7: 1502.7588 | M7: 1502.7588 | N7: 1502.7588 | O7: 1241.4752 | P7: 727.47052 | Q7: 1502.7588 | R7: 710.1917 | S7: 1502.7588 | T7: 701.12316 | U7: 1502.7588 | V7: 1502.7588 | W7: 1502.7588 | X7: 714.47254 | Y7: 705.53763 | Z7: 1502.7588 | AA7: 921.28876 | AB7: 1502.7588 | AC7: 1502.7588 | AD7: 704.3193 | AE7: 1502.7588 | AF7: 1502.7588 | AG7: 710.77744 | AH7: 1502.7588 | AI7: 705.84609 | AJ7: 961.8229 | AK7: 1502.7588 | AL7: 1502.7588 | AM7: 1229.8179 | AN7: 724.82967 | AO7: 1502.7588 | AP7: 1502.7588 | AQ7: 1399.7728 | AR7: 1502.7588 | AS7: 1502.7588 | AT7: 1502.7588 | AU7: 1502.7588 | AV7: 710.67486 | AW7: 720.79493
A8: 545.96822 | B8: 516.84844 | C8: 1694.9876 | D8: 547.45594 | E8: 538.30258 | F8: 1694.9876 | G8: 487.52567 | H8: 1694.9876 | I8: 1029.4403 | J8: 544.74364 | K8: 1250.7964 | L8: 507.18391 | M8: 1063.4052 | N8: 597.99902 | O8: 494.6756 | P8: 529.66114 | Q8: 1588.4412 | R8: 1167.4542 | S8: 1307.7065 | T8: 1344.0595 | U8: 1195.21 | V8: 844.2805 | W8: 1297.7474 | X8: 494.69433 | Y8: 519.2728 | Z8: 1694.9876 | AA8: 575.59443 | AB8: 1154.8805 | AC8: 512.53888 | AD8: 516.35316 | AE8: 542.51508 | AF8: 1354.7042 | AG8: 1237.7781 | AH8: 1694.9876 | AI8: 498.85292 | AJ8: 986.52221 | AK8: 1028.2604 | AL8: 1694.9876 | AM8: 578.73144 | AN8: 548.06037 | AO8: 1451.2548 | AP8: 1580.1477 | AQ8: 1694.9876 | AR8: 1174.0244 | AS8: 1439.724 | AT8: 1694.9876 | AU8: 1694.9876 | AV8: 592.6622 | AW8: 550.24977
A9: 1204.1391 | B9: 1145.8003 | C9: 1186.4364 | D9: 1155.5251 | E9: 1188.7549 | F9: 1100.7952 | G9: 1123.5995 | H9: 1092.7515 | I9: 1101.7665 | J9: 1172.5162 | K9: 1166.331 | L9: 1140.5056 | M9: 1159.3608 | N9: 1104.3503 | O9: 1136.1404 | P9: 1133.3264 | Q9: 1139.0258 | R9: 1109.2308 | S9: 1112.2759 | T9: 1122.4305 | U9: 1135.7799 | V9: 1134.2568 | W9: 1141.3233 | X9: 1148.2913 | Y9: 1148.4145 | Z9: 1131.099 | AA9: 1128.3857 | AB9: 1233.5716 | AC9: 1150.0601 | AD9: 1134.2834 | AE9: 1149.792 | AF9: 1140.9636 | AG9: 1143.6766 | AH9: 1076.6214 | AI9: 1126.8823 | AJ9: 1151.211 | AK9: 1156.3855 | AL9: 1095.6243 | AM9: 1122.2936 | AN9: 1161.8731 | AO9: 1167.9104 | AP9: 1112.8405 | AQ9: 1147.5306 | AR9: 1078.9037 | AS9: 1089.9687 | AT9: 1107.8565 | AU9: 1137.3948 | AV9: 1131.1601 | AW9: 1161.5498
A10: 1261.0652 | B10: 1235.0983 | C10: 1243.1296 | D10: 1233.4523 | E10: 1254.8382 | F10: 802.27317 | G10: 1259.5743 | H10: 1310.7427 | I10: 1237.0712 | J10: 1245.3618 | K10: 1271.3087 | L10: 1217.2438 | M10: 1248.6385 | N10: 839.31102 | O10: 1234.7726 | P10: 1232.3765 | Q10: 1238.0014 | R10: 1228.3736 | S10: 1228.5044 | T10: 1236.6561 | U10: 1029.1243 | V10: 944.82336 | W10: 1059.9235 | X10: 1236.2501 | Y10: 1238.3108 | Z10: 1261.8027 | AA10: 1223.6969 | AB10: 1257.3213 | AC10: 1237.6988 | AD10: 1230.7058 | AE10: 1234.2487 | AF10: 1243.337 | AG10: 1252.7423 | AH10: 653.81982 | AI10: 1234.756 | AJ10: 1231.4031 | AK10: 1234.3891 | AL10: 954.22269 | AM10: 1210.4095 | AN10: 1251.7292 | AO10: 1235.8495 | AP10: 851.4236 | AQ10: 1237.4369 | AR10: 1365.5019 | AS10: 594.14084 | AT10: 839.31972 | AU10: 856.39962 | AV10: 1256.0506 | AW10: 1243.1781
A11: 1498.788 | B11: 1188.5273 | C11: 1057.7413 | D11: 1498.788 | E11: 1498.788 | F11: 463.17222 | G11: 617.41109 | H11: 419.23922 | I11: 1498.788 | J11: 1245.0694 | K11: 1498.788 | L11: 1319.5845 | M11: 1498.788 | N11: 490.18453 | O11: 1498.788 | P11: 1498.788 | Q11: 975.577 | R11: 1498.788 | S11: 1234.1426 | T11: 1473.7177 | U11: 274.13097 | V11: 275.42874 | W11: 500.02549 | X11: 1459.7854 | Y11: 1498.788 | Z11: 1032.7983 | AA11: 1443.8035 | AB11: 1459.7854 | AC11: 907.12177 | AD11: 1498.788 | AE11: 1498.788 | AF11: 1342.6688 | AG11: 1498.788 | AH11: 204.38267 | AI11: 1498.788 | AJ11: 1498.788 | AK11: 1310.4576 | AL11: 430.90508 | AM11: 1013.7826 | AN11: 1498.788 | AO11: 1498.788 | AP11: 681.56687 | AQ11: 1272.9185 | AR11: 454.91708 | AS11: 311.36615 | AT11: 368.66752 | AU11: 363.57776 | AV11: 1498.788 | AW11: 1498.788
A12: 1514.8212 | B12: 214.95967 | C12: 447.03166 | D12: 902.92495 | E12: 321.41805 | F12: 288.81573 | G12: 172.36873 | H12: 330.97556 | I12: 404.87353 | J12: 222.26957 | K12: 957.38797 | L12: 208.68389 | M12: 585.45091 | N12: 176.96885 | O12: 433.76366 | P12: 1083.668 | Q12: 303.69984 | R12: 877.25617 | S12: 208.51709 | T12: 434.46356 | U12: 180.46727 | V12: 132.38834 | W12: 306.28987 | X12: 964.63875 | Y12: 1400.7928 | Z12: 182.46711 | AA12: 451.73016 | AB12: 924.6295 | AC12: 280.49136 | AD12: 410.31397 | AE12: 637.57828 | AF12: 283.14554 | AG12: 926.88785 | AH12: 208.38195 | AI12: 862.69874 | AJ12: 1514.8212 | AK12: 205.30949 | AL12: 234.21125 | AM12: 252.09769 | AN12: 1514.8212 | AO12: 358.64505 | AP12: 394.9026 | AQ12: 281.93692 | AR12: 461.95 | AS12: 221.33466 | AT12: 254.00599 | AU12: 236.22734 | AV12: 873.76881 | AW12: 1514.8212
... A84: 1091.2982 | B84: 447.03166 | C84: 1514.8212 | D84: 227.72293 | E84: 705.36568 | F84: 509.98662 | G84: 330.97556 | H84: 1026.6348 | I84: 1228.459 | J84: 539.55062 | K84: 607.60215 | L84: 189.06535 | M84: 465.73013 | N84: 477.52741 | O84: 837.33173 | P84: 303.69984 | Q84: 1050.9505 | R84: 1112.8352 | S84: 551.08867 | T84: 180.46727 | U84: 260.67408 | V84: 528.2016 | W84: 1514.8212 | X84: 1514.8212 | Y84: 182.46711 | Z84: 1473.6143 | AA84: 472.63297 | AB84: 280.49136 | AC84: 1063.1768 | AD84: 609.80044 | AE84: 428.79367 | AF84: 574.35491 | AG84: 208.38195 | AH84: 1121.0246 | AI84: 899.58583 | AJ84: 205.30949 | AK84: 234.21125 | AL84: 1012.9777 | AM84: 1514.8212 | AN84: 718.80492 | AO84: 792.25331 | AP84: 541.8537 | AQ84: 461.95 | AR84: 382.5834 | AS84: 254.00599 | AT84: 236.22734 | AU84: 1514.8212 | AV84: 1514.8212 | AW84: 542.58057

Sheet P_NOW_val_ARD
A1: 61.38744 | B1: 61.38744 | C1: 61.38744 | D1: 61.38744 | E1: 61.38744 | F1: 61.38744 | G1: 61.38744 | H1: 61.38744 | I1: 61.38744 | J1: 61.38744 | K1: 61.38744 | L1: 61.38744 | M1: 61.38744 | N1: 61.38744 | O1: 61.38744 | P1: 61.38744 | Q1: 61.38744 | R1: 61.38744 | S1: 61.38744 | T1: 61.38744 | U1: 61.38744 | V1: 61.38744 | W1: 61.38744 | X1: 61.38744 | Y1: 61.38744 | Z1: 61.38744 | AA1: 61.38744 | AB1: 61.38744 | AC1: 61.38744 | AD1: 61.38744 | AE1: 61.38744 | AF1: 61.38744 | AG1: 61.38744 | AH1: 61.38744 | AI1: 61.38744 | AJ1: 61.38744 | AK1: 61.38744 | AL1: 61.38744 | AM1: 61.38744 | AN1: 61.38744 | AO1: 61.38744 | AP1: 61.38744 | AQ1: 61.38744 | AR1: 61.38744 | AS1: 61.38744 | AT1: 61.38744 | AU1: 61.38744 | AV1: 61.38744 | AW1: 61.38744
A2: 66.3648 | B2: 66.3648 | C2: 66.3648 | D2: 66.3648 | E2: 66.3648 | F2: 66.3648 | G2: 66.3648 | H2: 66.3648 | I2: 66.3648 | J2: 66.3648 | K2: 66.3648 | L2: 66.3648 | M2: 66.3648 | N2: 66.3648 | O2: 66.3648 | P2: 66.3648 | Q2: 66.3648 | R2: 66.3648 | S2: 66.3648 | T2: 66.3648 | U2: 66.3648 | V2: 66.3648 | W2: 66.3648 | X2: 66.3648 | Y2: 66.3648 | Z2: 66.3648 | AA2: 66.3648 | AB2: 66.3648 | AC2: 66.3648 | AD2: 66.3648 | AE2: 66.3648 | AF2: 66.3648 | AG2: 66.3648 | AH2: 66.3648 | AI2: 66.3648 | AJ2: 66.3648 | AK2: 66.3648 | AL2: 66.3648 | AM2: 66.3648 | AN2: 66.3648 | AO2: 66.3648 | AP2: 66.3648 | AQ2: 66.3648 | AR2: 66.3648 | AS2: 66.3648 | AT2: 66.3648 | AU2: 66.3648 | AV2: 66.3648 | AW2: 66.3648
A3: 54.69744 | B3: 54.69744 | C3: 54.69744 | D3: 54.69744 | E3: 54.69744 | F3: 54.69744 | G3: 54.69744 | H3: 54.69744 | I3: 54.69744 | J3: 54.69744 | K3: 54.69744 | L3: 54.69744 | M3: 54.69744 | N3: 54.69744 | O3: 54.69744 | P3: 54.69744 | Q3: 54.69744 | R3: 54.69744 | S3: 54.69744 | T3: 54.69744 | U3: 54.69744 | V3: 54.69744 | W3: 54.69744 | X3: 54.69744 | Y3: 54.69744 | Z3: 54.69744 | AA3: 54.69744 | AB3: 54.69744 | AC3: 54.69744 | AD3: 54.69744 | AE3: 54.69744 | AF3: 54.69744 | AG3: 54.69744 | AH3: 54.69744 | AI3: 54.69744 | AJ3: 54.69744 | AK3: 54.69744 | AL3: 54.69744 | AM3: 54.69744 | AN3: 54.69744 | AO3: 54.69744 | AP3: 54.69744 | AQ3: 54.69744 | AR3: 54.69744 | AS3: 54.69744 | AT3: 54.69744 | AU3: 54.69744 | AV3: 54.69744 | AW3: 54.69744
A4: 43.96668 | B4: 43.96668 | C4: 43.96668 | D4: 43.96668 | E4: 43.96668 | F4: 43.96668 | G4: 43.96668 | H4: 43.96668 | I4: 43.96668 | J4: 43.96668 | K4: 43.96668 | L4: 43.96668 | M4: 43.96668 | N4: 43.96668 | O4: 43.96668 | P4: 43.96668 | Q4: 43.96668 | R4: 43.96668 | S4: 43.96668 | T4: 43.96668 | U4: 43.96668 | V4: 43.96668 | W4: 43.96668 | X4: 43.96668 | Y4: 43.96668 | Z4: 43.96668 | AA4: 43.96668 | AB4: 43.96668 | AC4: 43.96668 | AD4: 43.96668 | AE4: 43.96668 | AF4: 43.96668 | AG4: 43.96668 | AH4: 43.96668 | AI4: 43.96668 | AJ4: 43.96668 | AK4: 43.96668 | AL4: 43.96668 | AM4: 43.96668 | AN4: 43.96668 | AO4: 43.96668 | AP4: 43.96668 | AQ4: 43.96668 | AR4: 43.96668 | AS4: 43.96668 | AT4: 43.96668 | AU4: 43.96668 | AV4: 43.96668 | AW4: 43.96668
A5: 53.7876 | B5: 53.7876 | C5: 53.7876 | D5: 53.7876 | E5: 53.7876 | F5: 53.7876 | G5: 53.7876 | H5: 53.7876 | I5: 53.7876 | J5: 53.7876 | K5: 53.7876 | L5: 53.7876 | M5: 53.7876 | N5: 53.7876 | O5: 53.7876 | P5: 53.7876 | Q5: 53.7876 | R5: 53.7876 | S5: 53.7876 | T5: 53.7876 | U5: 53.7876 | V5: 53.7876 | W5: 53.7876 | X5: 53.7876 | Y5: 53.7876 | Z5: 53.7876 | AA5: 53.7876 | AB5: 53.7876 | AC5: 53.7876 | AD5: 53.7876 | AE5: 53.7876 | AF5: 53.7876 | AG5: 53.7876 | AH5: 53.7876 | AI5: 53.7876 | AJ5: 53.7876 | AK5: 53.7876 | AL5: 53.7876 | AM5: 53.7876 | AN5: 53.7876 | AO5: 53.7876 | AP5: 53.7876 | AQ5: 53.7876 | AR5: 53.7876 | AS5: 53.7876 | AT5: 53.7876 | AU5: 53.7876 | AV5: 53.7876 | AW5: 53.7876
A6: 75.48996 | B6: 75.48996 | C6: 75.48996 | D6: 75.48996 | E6: 75.48996 | F6: 75.48996 | G6: 75.48996 | H6: 75.48996 | I6: 75.48996 | J6: 75.48996 | K6: 75.48996 | L6: 75.48996 | M6: 75.48996 | N6: 75.48996 | O6: 75.48996 | P6: 75.48996 | Q6: 75.48996 | R6: 75.48996 | S6: 75.48996 | T6: 75.48996 | U6: 75.48996 | V6: 75.48996 | W6: 75.48996 | X6: 75.48996 | Y6: 75.48996 | Z6: 75.48996 | AA6: 75.48996 | AB6: 75.48996 | AC6: 75.48996 | AD6: 75.48996 | AE6: 75.48996 | AF6: 75.48996 | AG6: 75.48996 | AH6: 75.48996 | AI6: 75.48996 | AJ6: 75.48996 | AK6: 75.48996 | AL6: 75.48996 | AM6: 75.48996 | AN6: 75.48996 | AO6: 75.48996 | AP6: 75.48996 | AQ6: 75.48996 | AR6: 75.48996 | AS6: 75.48996 | AT6: 75.48996 | AU6: 75.48996 | AV6: 75.48996 | AW6: 75.48996
A7: 96.4029 | B7: 105.1668 | C7: 105.1668 | D7: 94.377877 | E7: 105.1668 | F7: 105.1668 | G7: 105.1668 | H7: 105.1668 | I7: 105.1668 | J7: 105.1668 | K7: 105.1668 | L7: 105.1668 | M7: 105.1668 | N7: 105.1668 | O7: 96.4029 | P7: 105.1668 | Q7: 105.1668 | R7: 105.1668 | S7: 105.1668 | T7: 105.1668 | U7: 105.1668 | V7: 92.760928 | W7: 105.1668 | X7: 105.1668 | Y7: 105.1668 | Z7: 105.1668 | AA7: 105.1668 | AB7: 105.1668 | AC7: 105.1668 | AD7: 105.1668 | AE7: 105.1668 | AF7: 105.1668 | AG7: 105.1668 | AH7: 105.1668 | AI7: 105.1668 | AJ7: 105.1668 | AK7: 96.4029 | AL7: 105.1668 | AM7: 96.4029 | AN7: 105.1668 | AO7: 105.1668 | AP7: 105.1668 | AQ7: 96.4029 | AR7: 105.1668 | AS7: 105.1668 | AT7: 105.1668 | AU7: 105.1668 | AV7: 105.1668 | AW7: 105.1668
A8: 116.1384 | B8: 116.1384 | C8: 116.1384 | D8: 116.1384 | E8: 116.1384 | F8: 77.4256 | G8: 116.1384 | H8: 116.1384 | I8: 116.1384 | J8: 116.1384 | K8: 116.1384 | L8: 116.1384 | M8: 116.1384 | N8: 38.7128 | O8: 116.1384 | P8: 116.1384 | Q8: 116.1384 | R8: 35.52716 | S8: 116.1384 | T8: 116.1384 | U8: 33.231094 | V8: 38.7128 | W8: 116.1384 | X8: 116.1384 | Y8: 116.1384 | Z8: 116.1384 | AA8: 38.7128 | AB8: 116.1384 | AC8: 116.1384 | AD8: 116.1384 | AE8: 116.1384 | AF8: 116.1384 | AG8: 116.1384 | AH8: 26.044979 | AI8: 116.1384 | AJ8: 116.1384 | AK8: 116.1384 | AL8: 116.1384 | AM8: 38.7128 | AN8: 116.1384 | AO8: 116.1384 | AP8: 116.1384 | AQ8: 116.1384 | AR8: 35.645806 | AS8: 9.6782 | AT8: 116.1384 | AU8: 116.1384 | AV8: 38.7128 | AW8: 116.1384
A9: 107.8428 | B9: 93.877263 | C9: 93.877263 | D9: 93.877263 | E9: 107.8428 | F9: 107.8428 | G9: 98.8559 | H9: 107.8428 | I9: 93.877263 | J9: 93.877263 | K9: 93.877263 | L9: 93.877263 | M9: 93.877263 | N9: 93.877263 | O9: 93.877263 | P9: 93.877263 | Q9: 93.877263 | R9: 93.877263 | S9: 93.877263 | T9: 93.877263 | U9: 93.877263 | V9: 104.91777 | W9: 93.877263 | X9: 93.877263 | Y9: 93.877263 | Z9: 93.877263 | AA9: 93.877263 | AB9: 107.8428 | AC9: 93.877263 | AD9: 93.877263 | AE9: 93.877263 | AF9: 93.877263 | AG9: 93.877263 | AH9: 107.8428 | AI9: 93.877263 | AJ9: 93.877263 | AK9: 93.877263 | AL9: 107.8428 | AM9: 93.877263 | AN9: 93.877263 | AO9: 93.877263 | AP9: 93.877263 | AQ9: 93.877263 | AR9: 107.8428 | AS9: 107.8428 | AT9: 93.877263 | AU9: 98.8559 | AV9: 93.877263 | AW9: 93.877263
A10: 47.1645 | B10: 47.1645 | C10: 47.1645 | D10: 47.1645 | E10: 47.1645 | F10: 113.1948 | G10: 73.800612 | H10: 113.1948 | I10: 47.1645 | J10: 47.1645 | K10: 47.1645 | L10: 75.4632 | M10: 47.1645 | N10: 113.1948 | O10: 47.1645 | P10: 47.1645 | Q10: 47.1645 | R10: 47.1645 | S10: 47.1645 | T10: 47.1645 | U10: 113.1948 | V10: 113.1948 | W10: 113.1948 | X10: 103.7619 | Y10: 47.1645 | Z10: 47.1645 | AA10: 47.1645 | AB10: 49.969217 | AC10: 47.1645 | AD10: 47.1645 | AE10: 47.1645 | AF10: 47.1645 | AG10: 47.1645 | AH10: 113.1948 | AI10: 47.1645 | AJ10: 47.1645 | AK10: 47.1645 | AL10: 113.1948 | AM10: 75.4632 | AN10: 47.1645 | AO10: 47.1645 | AP10: 113.1948 | AQ10: 47.1645 | AR10: 113.1948 | AS10: 113.1948 | AT10: 113.1948 | AU10: 113.1948 | AV10: 47.1645 | AW10: 47.1645
A11: 111.16104 | B11: 111.16104 | C11: 111.16104 | D11: 111.16104 | E11: 111.16104 | F11: 111.16104 | G11: 111.16104 | H11: 111.16104 | I11: 111.16104 | J11: 111.16104 | K11: 111.16104 | L11: 111.16104 | M11: 111.16104 | N11: 111.16104 | O11: 111.16104 | P11: 111.16104 | Q11: 111.16104 | R11: 111.16104 | S11: 111.16104 | T11: 111.16104 | U11: 111.16104 | V11: 111.16104 | W11: 111.16104 | X11: 83.37078 | Y11: 111.16104 | Z11: 111.16104 | AA11: 111.16104 | AB11: 83.37078 | AC11: 111.16104 | AD11: 111.16104 | AE11: 111.16104 | AF11: 111.16104 | AG11: 111.16104 | AH11: 111.16104 | AI11: 111.16104 | AJ11: 111.16104 | AK11: 111.16104 | AL11: 111.16104 | AM11: 111.16104 | AN11: 111.16104 | AO11: 111.16104 | AP11: 111.16104 | AQ11: 111.16104 | AR11: 111.16104 | AS11: 111.16104 | AT11: 111.16104 | AU11: 111.16104 | AV11: 111.16104 | AW11: 111.16104
A12: 82.6884 | B12: 82.6884 | C12: 82.6884 | D12: 82.6884 | E12: 82.6884 | F12: 82.6884 | G12: 82.6884 | H12: 82.6884 | I12: 82.6884 | J12: 82.6884 | K12: 82.6884 | L12: 82.6884 | M12: 82.6884 | N12: 82.6884 | O12: 82.6884 | P12: 82.6884 | Q12: 82.6884 | R12: 82.6884 | S12: 82.6884 | T12: 82.6884 | U12: 82.6884 | V12: 82.6884 | W12: 82.6884 | X12: 82.6884 | Y12: 82.6884 | Z12: 82.6884 | AA12: 82.6884 | AB12: 82.6884 | AC12: 82.6884 | AD12: 82.6884 | AE12: 82.6884 | AF12: 82.6884 | AG12: 82.6884 | AH12: 82.6884 | AI12: 82.6884 | AJ12: 82.6884 | AK12: 82.6884 | AL12: 82.6884 | AM12: 82.6884 | AN12: 82.6884 | AO12: 82.6884 | AP12: 82.6884 | AQ12: 82.6884 | AR12: 82.6884 | AS12: 82.6884 | AT12: 82.6884 | AU12: 82.6884 | AV12: 82.6884 | AW12: 82.6884
... A84: 82.6884 | B84: 82.6884 | C84: 82.6884 | D84: 82.6884 | E84: 82.6884 | F84: 82.6884 | G84: 82.6884 | H84: 82.6884 | I84: 82.6884 | J84: 82.6884 | K84: 82.6884 | L84: 82.6884 | M84: 82.6884 | N84: 82.6884 | O84: 82.6884 | P84: 82.6884 | Q84: 82.6884 | R84: 82.6884 | S84: 82.6884 | T84: 82.6884 | U84: 82.6884 | V84: 82.6884 | W84: 82.6884 | X84: 82.6884 | Y84: 82.6884 | Z84: 82.6884 | AA84: 82.6884 | AB84: 82.6884 | AC84: 82.6884 | AD84: 82.6884 | AE84: 82.6884 | AF84: 82.6884 | AG84: 82.6884 | AH84: 82.6884 | AI84: 82.6884 | AJ84: 82.6884 | AK84: 82.6884 | AL84: 82.6884 | AM84: 82.6884 | AN84: 82.6884 | AO84: 82.6884 | AP84: 82.6884 | AQ84: 82.6884 | AR84: 82.6884 | AS84: 82.6884 | AT84: 82.6884 | AU84: 82.6884 | AV84: 82.6884 | AW84: 82.6884

Sheet SPOT_EXP_USH_NOW 
A1: -3384.1051 | B1: -3381.8176 | C1: -3379.7967 | D1: -3388.905 | E1: -3381.869 | F1: -3388.1841 | G1: -3381.5695 | H1: -3381.358 | I1: -3382.019 | J1: -3367.8576 | K1: -3387.27 | L1: -3385.8733 | M1: -3385.9374 | N1: -3374.3343 | O1: -3377.9334 | P1: -3380.3243 | Q1: -3386.4731 | R1: -3383.5741 | S1: -3382.1105 | T1: -3387.4085 | U1: -3373.5196 | V1: -3384.1678 | W1: -3380.3456 | X1: -3378.9618 | Y1: -3383.398 | Z1: -3382.2927 | AA1: -3390.108 | AB1: -3378.9161 | AC1: -3384.9879 | AD1: -3387.2687 | AE1: -3388.1814 | AF1: -3381.4348 | AG1: -3384.5198 | AH1: -3379.1435 | AI1: -3378.7543 | AJ1: -3381.1671 | AK1: -3384.3295 | AL1: -3385.4204 | AM1: -3382.5984 | AN1: -3380.2515 | AO1: -3375.1406 | AP1: -3382.8047 | AQ1: -3380.2964 | AR1: -3386.3233 | AS1: -3388.9947 | AT1: -3383.3716 | AU1: -3382.2572 | AV1: -3382.1073 | AW1: -3383.8918
A2: 957.5234 | B2: 980.17334 | C2: 967.63942 | D2: 960.69024 | E2: 971.29362 | F2: 962.00461 | G2: 973.49975 | H2: 961.93157 | I2: 966.25872 | J2: 974.64372 | K2: 969.29683 | L2: 965.85539 | M2: 999.88653 | N2: 971.10409 | O2: 975.6014 | P2: 964.04318 | Q2: 964.87494 | R2: 959.81082 | S2: 971.90672 | T2: 967.23661 | U2: 977.87961 | V2: 959.53206 | W2: 968.71103 | X2: 973.66919 | Y2: 963.20152 | Z2: 972.20675 | AA2: 966.71953 | AB2: 975.08103 | AC2: 967.3836 | AD2: 964.58999 | AE2: 976.7162 | AF2: 971.7932 | AG2: 971.87837 | AH2: 986.11487 | AI2: 984.61249 | AJ2: 963.1253 | AK2: 964.35862 | AL2: 972.55355 | AM2: 969.92087 | AN2: 967.00141 | AO2: 968.21162 | AP2: 968.25739 | AQ2: 964.44809 | AR2: 973.58583 | AS2: 967.78915 | AT2: 965.02547 | AU2: 966.9916 | AV2: 965.49547 | AW2: 965.97163
