Workbook

Sheet Price diff
A1: Date | B1: HLH [$/MWh] | C1: LLH [$/MWh] | D1: 1 | E1: 2 | F1: 3 | G1: 4 | H1: 5 | I1: 6 | J1: 7 | K1: 8 | L1: 9 | M1: 10 | N1: 11 | O1: 12 | P1: 13 | Q1: 14 | R1: 15 | S1: 16 | T1: 17 | U1: 18 | V1: 19 | W1: 20 | X1: 21 | Y1: 22 | Z1: 23 | AA1: 24 | AB1: 25 | AC1: 26 | AD1: 27 | AE1: 28 | AF1: 29 | AG1: 30 | AH1: 31 | AI1: 32 | AJ1: 33 | AK1: 34 | AL1: 35 | AM1: 36 | AN1: 37 | AO1: 38 | AP1: 39 | AQ1: 40 | AR1: 41 | AS1: 42 | AT1: 43 | AU1: 44 | AV1: 45 | AW1: 46 | AX1: 47 | AY1: 48 | AZ1: 49
A2: 44531 | B2: 50.76 | C2: 42.414 | D2: =(SUMPRODUCT(OFFSET('BlocksFinal (Kyle and Naser)'!$A1,0,(D$1-1)*10,1,3),{2,6,8})/16-$B2)*2/3+(SUMPRODUCT(OFFSET('BlocksFinal (Kyle and Naser)'!$A1,0,(D$1-1)*10+3,1,2),{6,2})/8-$C2)/3 -> -2.415408 | E2: =(SUMPRODUCT(OFFSET('BlocksFinal (Kyle and Naser)'!$A1,0,(E$1-1)*10,1,3),{2,6,8})/16-$B2)*2/3+(SUMPRODUCT(OFFSET('BlocksFinal (Kyle and Naser)'!$A1,0,(E$1-1)*10+3,1,2),{6,2})/8-$C2)/3 -> 8.5937003 | F2: =(SUMPRODUCT(OFFSET('BlocksFinal (Kyle and Naser)'!$A1,0,(F$1-1)*10,1,3),{2,6,8})/16-$B2)*2/3+(SUMPRODUCT(OFFSET('BlocksFinal (Kyle and Naser)'!$A1,0,(F$1-1)*10+3,1,2),{6,2})/8-$C2)/3 -> -13.242944 | G2: =(SUMPRODUCT(OFFSET('BlocksFinal (Kyle and Naser)'!$A1,0,(G$1-1)*10,1,3),{2,6,8})/16-$B2)*2/3+(SUMPRODUCT(OFFSET('BlocksFinal (Kyle and Naser)'!$A1,0,(G$1-1)*10+3,1,2),{6,2})/8-$C2)/3 -> 1.0233641 | H2: =(SUMPRODUCT(OFFSET('BlocksFinal (Kyle and Naser)'!$A1,0,(H$1-1)*10,1,3),{2,6,8})/16-$B2)*2/3+(SUMPRODUCT(OFFSET('BlocksFinal (Kyle and Naser)'!$A1,0,(H$1-1)*10+3,1,2),{6,2})/8-$C2)/3 -> -3.6281539 | I2: =(SUMPRODUCT(OFFSET('BlocksFinal (Kyle and Naser)'!$A1,0,(I$1-1)*10,1,3),{2,6,8})/16-$B2)*2/3+(SUMPRODUCT(OFFSET('BlocksFinal (Kyle and Naser)'!$A1,0,(I$1-1)*10+3,1,2),{6,2})/8-$C2)/3 -> -7.9669686 | J2: =(SUMPRODUCT(OFFSET('BlocksFinal (Kyle and Naser)'!$A1,0,(J$1-1)*10,1,3),{2,6,8})/16-$B2)*2/3+(SUMPRODUCT(OFFSET('BlocksFinal (Kyle and Naser)'!$A1,0,(J$1-1)*10+3,1,2),{6,2})/8-$C2)/3 -> -1.6506275 | K2: =(SUMPRODUCT(OFFSET('BlocksFinal (Kyle and Naser)'!$A1,0,(K$1-1)*10,1,3),{2,6,8})/16-$B2)*2/3+(SUMPRODUCT(OFFSET('BlocksFinal (Kyle and Naser)'!$A1,0,(K$1-1)*10+3,1,2),{6,2})/8-$C2)/3 -> -3.3513559 | ... AZ2: =(SUMPRODUCT(OFFSET('BlocksFinal (Kyle and Naser)'!$A1,0,(AZ$1-1)*10,1,3),{2,6,8})/16-$B2)*2/3+(SUMPRODUCT(OFFSET('BlocksFinal (Kyle and Naser)'!$A1,0,(AZ$1-1)*10+3,1,2),{6,2})/8-$C2)/3 -> 1.817182
A3: 44562 | B3: 65.25 | C3: 49.35 | D3: =(SUMPRODUCT(OFFSET('BlocksFinal (Kyle and Naser)'!$A2,0,(D$1-1)*10,1,3),{2,6,8})/16-$B3)*2/3+(SUMPRODUCT(OFFSET('BlocksFinal (Kyle and Naser)'!$A2,0,(D$1-1)*10+3,1,2),{6,2})/8-$C3)/3 -> -1.0119791 | E3: =(SUMPRODUCT(OFFSET('BlocksFinal (Kyle and Naser)'!$A2,0,(E$1-1)*10,1,3),{2,6,8})/16-$B3)*2/3+(SUMPRODUCT(OFFSET('BlocksFinal (Kyle and Naser)'!$A2,0,(E$1-1)*10+3,1,2),{6,2})/8-$C3)/3 -> -13.625533 | F3: =(SUMPRODUCT(OFFSET('BlocksFinal (Kyle and Naser)'!$A2,0,(F$1-1)*10,1,3),{2,6,8})/16-$B3)*2/3+(SUMPRODUCT(OFFSET('BlocksFinal (Kyle and Naser)'!$A2,0,(F$1-1)*10+3,1,2),{6,2})/8-$C3)/3 -> -2.7078483 | G3: =(SUMPRODUCT(OFFSET('BlocksFinal (Kyle and Naser)'!$A2,0,(G$1-1)*10,1,3),{2,6,8})/16-$B3)*2/3+(SUMPRODUCT(OFFSET('BlocksFinal (Kyle and Naser)'!$A2,0,(G$1-1)*10+3,1,2),{6,2})/8-$C3)/3 -> 9.0213278 | H3: =(SUMPRODUCT(OFFSET('BlocksFinal (Kyle and Naser)'!$A2,0,(H$1-1)*10,1,3),{2,6,8})/16-$B3)*2/3+(SUMPRODUCT(OFFSET('BlocksFinal (Kyle and Naser)'!$A2,0,(H$1-1)*10+3,1,2),{6,2})/8-$C3)/3 -> 27.247735 | I3: =(SUMPRODUCT(OFFSET('BlocksFinal (Kyle and Naser)'!$A2,0,(I$1-1)*10,1,3),{2,6,8})/16-$B3)*2/3+(SUMPRODUCT(OFFSET('BlocksFinal (Kyle and Naser)'!$A2,0,(I$1-1)*10+3,1,2),{6,2})/8-$C3)/3 -> 0.6469392 | J3: =(SUMPRODUCT(OFFSET('BlocksFinal (Kyle and Naser)'!$A2,0,(J$1-1)*10,1,3),{2,6,8})/16-$B3)*2/3+(SUMPRODUCT(OFFSET('BlocksFinal (Kyle and Naser)'!$A2,0,(J$1-1)*10+3,1,2),{6,2})/8-$C3)/3 -> -11.295956 | K3: =(SUMPRODUCT(OFFSET('BlocksFinal (Kyle and Naser)'!$A2,0,(K$1-1)*10,1,3),{2,6,8})/16-$B3)*2/3+(SUMPRODUCT(OFFSET('BlocksFinal (Kyle and Naser)'!$A2,0,(K$1-1)*10+3,1,2),{6,2})/8-$C3)/3 -> 2.0117221 | ... AZ3: =(SUMPRODUCT(OFFSET('BlocksFinal (Kyle and Naser)'!$A2,0,(AZ$1-1)*10,1,3),{2,6,8})/16-$B3)*2/3+(SUMPRODUCT(OFFSET('BlocksFinal (Kyle and Naser)'!$A2,0,(AZ$1-1)*10+3,1,2),{6,2})/8-$C3)/3 -> -0.85792018
A4: 44593 | B4: 55.75 | C4: 45.45 | D4: =(SUMPRODUCT(OFFSET('BlocksFinal (Kyle and Naser)'!$A3,0,(D$1-1)*10,1,3),{2,6,8})/16-$B4)*2/3+(SUMPRODUCT(OFFSET('BlocksFinal (Kyle and Naser)'!$A3,0,(D$1-1)*10+3,1,2),{6,2})/8-$C4)/3 -> -7.0200789 | E4: =(SUMPRODUCT(OFFSET('BlocksFinal (Kyle and Naser)'!$A3,0,(E$1-1)*10,1,3),{2,6,8})/16-$B4)*2/3+(SUMPRODUCT(OFFSET('BlocksFinal (Kyle and Naser)'!$A3,0,(E$1-1)*10+3,1,2),{6,2})/8-$C4)/3 -> 18.294676 | F4: =(SUMPRODUCT(OFFSET('BlocksFinal (Kyle and Naser)'!$A3,0,(F$1-1)*10,1,3),{2,6,8})/16-$B4)*2/3+(SUMPRODUCT(OFFSET('BlocksFinal (Kyle and Naser)'!$A3,0,(F$1-1)*10+3,1,2),{6,2})/8-$C4)/3 -> -1.2767523 | G4: =(SUMPRODUCT(OFFSET('BlocksFinal (Kyle and Naser)'!$A3,0,(G$1-1)*10,1,3),{2,6,8})/16-$B4)*2/3+(SUMPRODUCT(OFFSET('BlocksFinal (Kyle and Naser)'!$A3,0,(G$1-1)*10+3,1,2),{6,2})/8-$C4)/3 -> 35.780614 | H4: =(SUMPRODUCT(OFFSET('BlocksFinal (Kyle and Naser)'!$A3,0,(H$1-1)*10,1,3),{2,6,8})/16-$B4)*2/3+(SUMPRODUCT(OFFSET('BlocksFinal (Kyle and Naser)'!$A3,0,(H$1-1)*10+3,1,2),{6,2})/8-$C4)/3 -> -6.4036451 | I4: =(SUMPRODUCT(OFFSET('BlocksFinal (Kyle and Naser)'!$A3,0,(I$1-1)*10,1,3),{2,6,8})/16-$B4)*2/3+(SUMPRODUCT(OFFSET('BlocksFinal (Kyle and Naser)'!$A3,0,(I$1-1)*10+3,1,2),{6,2})/8-$C4)/3 -> 9.4559095 | J4: =(SUMPRODUCT(OFFSET('BlocksFinal (Kyle and Naser)'!$A3,0,(J$1-1)*10,1,3),{2,6,8})/16-$B4)*2/3+(SUMPRODUCT(OFFSET('BlocksFinal (Kyle and Naser)'!$A3,0,(J$1-1)*10+3,1,2),{6,2})/8-$C4)/3 -> 9.1732375 | K4: =(SUMPRODUCT(OFFSET('BlocksFinal (Kyle and Naser)'!$A3,0,(K$1-1)*10,1,3),{2,6,8})/16-$B4)*2/3+(SUMPRODUCT(OFFSET('BlocksFinal (Kyle and Naser)'!$A3,0,(K$1-1)*10+3,1,2),{6,2})/8-$C4)/3 -> -9.1167797 | ... AZ4: =(SUMPRODUCT(OFFSET('BlocksFinal (Kyle and Naser)'!$A3,0,(AZ$1-1)*10,1,3),{2,6,8})/16-$B4)*2/3+(SUMPRODUCT(OFFSET('BlocksFinal (Kyle and Naser)'!$A3,0,(AZ$1-1)*10+3,1,2),{6,2})/8-$C4)/3 -> 5.4798102
A5: 44621 | B5: 37.25 | C5: 31.35 | D5: =(SUMPRODUCT(OFFSET('BlocksFinal (Kyle and Naser)'!$A4,0,(D$1-1)*10,1,3),{2,6,8})/16-$B5)*2/3+(SUMPRODUCT(OFFSET('BlocksFinal (Kyle and Naser)'!$A4,0,(D$1-1)*10+3,1,2),{6,2})/8-$C5)/3 -> 12.354466 | E5: =(SUMPRODUCT(OFFSET('BlocksFinal (Kyle and Naser)'!$A4,0,(E$1-1)*10,1,3),{2,6,8})/16-$B5)*2/3+(SUMPRODUCT(OFFSET('BlocksFinal (Kyle and Naser)'!$A4,0,(E$1-1)*10+3,1,2),{6,2})/8-$C5)/3 -> 38.475536 | F5: =(SUMPRODUCT(OFFSET('BlocksFinal (Kyle and Naser)'!$A4,0,(F$1-1)*10,1,3),{2,6,8})/16-$B5)*2/3+(SUMPRODUCT(OFFSET('BlocksFinal (Kyle and Naser)'!$A4,0,(F$1-1)*10+3,1,2),{6,2})/8-$C5)/3 -> -1.9102582 | G5: =(SUMPRODUCT(OFFSET('BlocksFinal (Kyle and Naser)'!$A4,0,(G$1-1)*10,1,3),{2,6,8})/16-$B5)*2/3+(SUMPRODUCT(OFFSET('BlocksFinal (Kyle and Naser)'!$A4,0,(G$1-1)*10+3,1,2),{6,2})/8-$C5)/3 -> 30.012947 | H5: =(SUMPRODUCT(OFFSET('BlocksFinal (Kyle and Naser)'!$A4,0,(H$1-1)*10,1,3),{2,6,8})/16-$B5)*2/3+(SUMPRODUCT(OFFSET('BlocksFinal (Kyle and Naser)'!$A4,0,(H$1-1)*10+3,1,2),{6,2})/8-$C5)/3 -> 39.404413 | I5: =(SUMPRODUCT(OFFSET('BlocksFinal (Kyle and Naser)'!$A4,0,(I$1-1)*10,1,3),{2,6,8})/16-$B5)*2/3+(SUMPRODUCT(OFFSET('BlocksFinal (Kyle and Naser)'!$A4,0,(I$1-1)*10+3,1,2),{6,2})/8-$C5)/3 -> 40.750279 | J5: =(SUMPRODUCT(OFFSET('BlocksFinal (Kyle and Naser)'!$A4,0,(J$1-1)*10,1,3),{2,6,8})/16-$B5)*2/3+(SUMPRODUCT(OFFSET('BlocksFinal (Kyle and Naser)'!$A4,0,(J$1-1)*10+3,1,2),{6,2})/8-$C5)/3 -> 14.930727 | K5: =(SUMPRODUCT(OFFSET('BlocksFinal (Kyle and Naser)'!$A4,0,(K$1-1)*10,1,3),{2,6,8})/16-$B5)*2/3+(SUMPRODUCT(OFFSET('BlocksFinal (Kyle and Naser)'!$A4,0,(K$1-1)*10+3,1,2),{6,2})/8-$C5)/3 -> 26.314629 | ... AZ5: =(SUMPRODUCT(OFFSET('BlocksFinal (Kyle and Naser)'!$A4,0,(AZ$1-1)*10,1,3),{2,6,8})/16-$B5)*2/3+(SUMPRODUCT(OFFSET('BlocksFinal (Kyle and Naser)'!$A4,0,(AZ$1-1)*10+3,1,2),{6,2})/8-$C5)/3 -> 19.31037
A6: 44652 | B6: 34.85 | C6: 28.6 | D6: =(SUMPRODUCT(OFFSET('BlocksFinal (Kyle and Naser)'!$A5,0,(D$1-1)*10,1,3),{2,6,8})/16-$B6)*2/3+(SUMPRODUCT(OFFSET('BlocksFinal (Kyle and Naser)'!$A5,0,(D$1-1)*10+3,1,2),{6,2})/8-$C6)/3 -> 41.231306 | E6: =(SUMPRODUCT(OFFSET('BlocksFinal (Kyle and Naser)'!$A5,0,(E$1-1)*10,1,3),{2,6,8})/16-$B6)*2/3+(SUMPRODUCT(OFFSET('BlocksFinal (Kyle and Naser)'!$A5,0,(E$1-1)*10+3,1,2),{6,2})/8-$C6)/3 -> 29.189313 | F6: =(SUMPRODUCT(OFFSET('BlocksFinal (Kyle and Naser)'!$A5,0,(F$1-1)*10,1,3),{2,6,8})/16-$B6)*2/3+(SUMPRODUCT(OFFSET('BlocksFinal (Kyle and Naser)'!$A5,0,(F$1-1)*10+3,1,2),{6,2})/8-$C6)/3 -> 17.893302 | G6: =(SUMPRODUCT(OFFSET('BlocksFinal (Kyle and Naser)'!$A5,0,(G$1-1)*10,1,3),{2,6,8})/16-$B6)*2/3+(SUMPRODUCT(OFFSET('BlocksFinal (Kyle and Naser)'!$A5,0,(G$1-1)*10+3,1,2),{6,2})/8-$C6)/3 -> 18.486101 | H6: =(SUMPRODUCT(OFFSET('BlocksFinal (Kyle and Naser)'!$A5,0,(H$1-1)*10,1,3),{2,6,8})/16-$B6)*2/3+(SUMPRODUCT(OFFSET('BlocksFinal (Kyle and Naser)'!$A5,0,(H$1-1)*10+3,1,2),{6,2})/8-$C6)/3 -> 22.502001 | I6: =(SUMPRODUCT(OFFSET('BlocksFinal (Kyle and Naser)'!$A5,0,(I$1-1)*10,1,3),{2,6,8})/16-$B6)*2/3+(SUMPRODUCT(OFFSET('BlocksFinal (Kyle and Naser)'!$A5,0,(I$1-1)*10+3,1,2),{6,2})/8-$C6)/3 -> 28.050183 | J6: =(SUMPRODUCT(OFFSET('BlocksFinal (Kyle and Naser)'!$A5,0,(J$1-1)*10,1,3),{2,6,8})/16-$B6)*2/3+(SUMPRODUCT(OFFSET('BlocksFinal (Kyle and Naser)'!$A5,0,(J$1-1)*10+3,1,2),{6,2})/8-$C6)/3 -> 32.144813 | K6: =(SUMPRODUCT(OFFSET('BlocksFinal (Kyle and Naser)'!$A5,0,(K$1-1)*10,1,3),{2,6,8})/16-$B6)*2/3+(SUMPRODUCT(OFFSET('BlocksFinal (Kyle and Naser)'!$A5,0,(K$1-1)*10+3,1,2),{6,2})/8-$C6)/3 -> 35.757987 | ... AZ6: =(SUMPRODUCT(OFFSET('BlocksFinal (Kyle and Naser)'!$A5,0,(AZ$1-1)*10,1,3),{2,6,8})/16-$B6)*2/3+(SUMPRODUCT(OFFSET('BlocksFinal (Kyle and Naser)'!$A5,0,(AZ$1-1)*10+3,1,2),{6,2})/8-$C6)/3 -> 22.791619
A7: 44682 | B7: 26.15 | C7: 13.35 | D7: =(SUMPRODUCT(OFFSET('BlocksFinal (Kyle and Naser)'!$A6,0,(D$1-1)*10,1,3),{2,6,8})/16-$B7)*2/3+(SUMPRODUCT(OFFSET('BlocksFinal (Kyle and Naser)'!$A6,0,(D$1-1)*10+3,1,2),{6,2})/8-$C7)/3 -> 15.956446 | E7: =(SUMPRODUCT(OFFSET('BlocksFinal (Kyle and Naser)'!$A6,0,(E$1-1)*10,1,3),{2,6,8})/16-$B7)*2/3+(SUMPRODUCT(OFFSET('BlocksFinal (Kyle and Naser)'!$A6,0,(E$1-1)*10+3,1,2),{6,2})/8-$C7)/3 -> 50.484522 | F7: =(SUMPRODUCT(OFFSET('BlocksFinal (Kyle and Naser)'!$A6,0,(F$1-1)*10,1,3),{2,6,8})/16-$B7)*2/3+(SUMPRODUCT(OFFSET('BlocksFinal (Kyle and Naser)'!$A6,0,(F$1-1)*10+3,1,2),{6,2})/8-$C7)/3 -> 20.27016 | G7: =(SUMPRODUCT(OFFSET('BlocksFinal (Kyle and Naser)'!$A6,0,(G$1-1)*10,1,3),{2,6,8})/16-$B7)*2/3+(SUMPRODUCT(OFFSET('BlocksFinal (Kyle and Naser)'!$A6,0,(G$1-1)*10+3,1,2),{6,2})/8-$C7)/3 -> 58.147597 | H7: =(SUMPRODUCT(OFFSET('BlocksFinal (Kyle and Naser)'!$A6,0,(H$1-1)*10,1,3),{2,6,8})/16-$B7)*2/3+(SUMPRODUCT(OFFSET('BlocksFinal (Kyle and Naser)'!$A6,0,(H$1-1)*10+3,1,2),{6,2})/8-$C7)/3 -> 35.337521 | I7: =(SUMPRODUCT(OFFSET('BlocksFinal (Kyle and Naser)'!$A6,0,(I$1-1)*10,1,3),{2,6,8})/16-$B7)*2/3+(SUMPRODUCT(OFFSET('BlocksFinal (Kyle and Naser)'!$A6,0,(I$1-1)*10+3,1,2),{6,2})/8-$C7)/3 -> 39.109134 | J7: =(SUMPRODUCT(OFFSET('BlocksFinal (Kyle and Naser)'!$A6,0,(J$1-1)*10,1,3),{2,6,8})/16-$B7)*2/3+(SUMPRODUCT(OFFSET('BlocksFinal (Kyle and Naser)'!$A6,0,(J$1-1)*10+3,1,2),{6,2})/8-$C7)/3 -> 33.914534 | K7: =(SUMPRODUCT(OFFSET('BlocksFinal (Kyle and Naser)'!$A6,0,(K$1-1)*10,1,3),{2,6,8})/16-$B7)*2/3+(SUMPRODUCT(OFFSET('BlocksFinal (Kyle and Naser)'!$A6,0,(K$1-1)*10+3,1,2),{6,2})/8-$C7)/3 -> 35.692923 | ... AZ7: =(SUMPRODUCT(OFFSET('BlocksFinal (Kyle and Naser)'!$A6,0,(AZ$1-1)*10,1,3),{2,6,8})/16-$B7)*2/3+(SUMPRODUCT(OFFSET('BlocksFinal (Kyle and Naser)'!$A6,0,(AZ$1-1)*10+3,1,2),{6,2})/8-$C7)/3 -> 36.592647
A8: 44713 | B8: 35.5 | C8: 14.5 | D8: =(SUMPRODUCT(OFFSET('BlocksFinal (Kyle and Naser)'!$A7,0,(D$1-1)*10,1,3),{2,6,8})/16-$B8)*2/3+(SUMPRODUCT(OFFSET('BlocksFinal (Kyle and Naser)'!$A7,0,(D$1-1)*10+3,1,2),{6,2})/8-$C8)/3 -> 32.266401 | E8: =(SUMPRODUCT(OFFSET('BlocksFinal (Kyle and Naser)'!$A7,0,(E$1-1)*10,1,3),{2,6,8})/16-$B8)*2/3+(SUMPRODUCT(OFFSET('BlocksFinal (Kyle and Naser)'!$A7,0,(E$1-1)*10+3,1,2),{6,2})/8-$C8)/3 -> 23.668769 | F8: =(SUMPRODUCT(OFFSET('BlocksFinal (Kyle and Naser)'!$A7,0,(F$1-1)*10,1,3),{2,6,8})/16-$B8)*2/3+(SUMPRODUCT(OFFSET('BlocksFinal (Kyle and Naser)'!$A7,0,(F$1-1)*10+3,1,2),{6,2})/8-$C8)/3 -> 39.191818 | G8: =(SUMPRODUCT(OFFSET('BlocksFinal (Kyle and Naser)'!$A7,0,(G$1-1)*10,1,3),{2,6,8})/16-$B8)*2/3+(SUMPRODUCT(OFFSET('BlocksFinal (Kyle and Naser)'!$A7,0,(G$1-1)*10+3,1,2),{6,2})/8-$C8)/3 -> 65.201447 | H8: =(SUMPRODUCT(OFFSET('BlocksFinal (Kyle and Naser)'!$A7,0,(H$1-1)*10,1,3),{2,6,8})/16-$B8)*2/3+(SUMPRODUCT(OFFSET('BlocksFinal (Kyle and Naser)'!$A7,0,(H$1-1)*10+3,1,2),{6,2})/8-$C8)/3 -> 60.078796 | I8: =(SUMPRODUCT(OFFSET('BlocksFinal (Kyle and Naser)'!$A7,0,(I$1-1)*10,1,3),{2,6,8})/16-$B8)*2/3+(SUMPRODUCT(OFFSET('BlocksFinal (Kyle and Naser)'!$A7,0,(I$1-1)*10+3,1,2),{6,2})/8-$C8)/3 -> 42.066008 | J8: =(SUMPRODUCT(OFFSET('BlocksFinal (Kyle and Naser)'!$A7,0,(J$1-1)*10,1,3),{2,6,8})/16-$B8)*2/3+(SUMPRODUCT(OFFSET('BlocksFinal (Kyle and Naser)'!$A7,0,(J$1-1)*10+3,1,2),{6,2})/8-$C8)/3 -> 27.375684 | K8: =(SUMPRODUCT(OFFSET('BlocksFinal (Kyle and Naser)'!$A7,0,(K$1-1)*10,1,3),{2,6,8})/16-$B8)*2/3+(SUMPRODUCT(OFFSET('BlocksFinal (Kyle and Naser)'!$A7,0,(K$1-1)*10+3,1,2),{6,2})/8-$C8)/3 -> 47.939943 | ... AZ8: =(SUMPRODUCT(OFFSET('BlocksFinal (Kyle and Naser)'!$A7,0,(AZ$1-1)*10,1,3),{2,6,8})/16-$B8)*2/3+(SUMPRODUCT(OFFSET('BlocksFinal (Kyle and Naser)'!$A7,0,(AZ$1-1)*10+3,1,2),{6,2})/8-$C8)/3 -> 27.277735
A9: 44743 | B9: 80.65 | C9: 32.55 | D9: =(SUMPRODUCT(OFFSET('BlocksFinal (Kyle and Naser)'!$A8,0,(D$1-1)*10,1,3),{2,6,8})/16-$B9)*2/3+(SUMPRODUCT(OFFSET('BlocksFinal (Kyle and Naser)'!$A8,0,(D$1-1)*10+3,1,2),{6,2})/8-$C9)/3 -> 0.34143833 | E9: =(SUMPRODUCT(OFFSET('BlocksFinal (Kyle and Naser)'!$A8,0,(E$1-1)*10,1,3),{2,6,8})/16-$B9)*2/3+(SUMPRODUCT(OFFSET('BlocksFinal (Kyle and Naser)'!$A8,0,(E$1-1)*10+3,1,2),{6,2})/8-$C9)/3 -> 1.0496924 | F9: =(SUMPRODUCT(OFFSET('BlocksFinal (Kyle and Naser)'!$A8,0,(F$1-1)*10,1,3),{2,6,8})/16-$B9)*2/3+(SUMPRODUCT(OFFSET('BlocksFinal (Kyle and Naser)'!$A8,0,(F$1-1)*10+3,1,2),{6,2})/8-$C9)/3 -> 14.140042 | G9: =(SUMPRODUCT(OFFSET('BlocksFinal (Kyle and Naser)'!$A8,0,(G$1-1)*10,1,3),{2,6,8})/16-$B9)*2/3+(SUMPRODUCT(OFFSET('BlocksFinal (Kyle and Naser)'!$A8,0,(G$1-1)*10+3,1,2),{6,2})/8-$C9)/3 -> 28.676677 | H9: =(SUMPRODUCT(OFFSET('BlocksFinal (Kyle and Naser)'!$A8,0,(H$1-1)*10,1,3),{2,6,8})/16-$B9)*2/3+(SUMPRODUCT(OFFSET('BlocksFinal (Kyle and Naser)'!$A8,0,(H$1-1)*10+3,1,2),{6,2})/8-$C9)/3 -> -13.44612 | I9: =(SUMPRODUCT(OFFSET('BlocksFinal (Kyle and Naser)'!$A8,0,(I$1-1)*10,1,3),{2,6,8})/16-$B9)*2/3+(SUMPRODUCT(OFFSET('BlocksFinal (Kyle and Naser)'!$A8,0,(I$1-1)*10+3,1,2),{6,2})/8-$C9)/3 -> -16.734584 | J9: =(SUMPRODUCT(OFFSET('BlocksFinal (Kyle and Naser)'!$A8,0,(J$1-1)*10,1,3),{2,6,8})/16-$B9)*2/3+(SUMPRODUCT(OFFSET('BlocksFinal (Kyle and Naser)'!$A8,0,(J$1-1)*10+3,1,2),{6,2})/8-$C9)/3 -> 0.80656199 | K9: =(SUMPRODUCT(OFFSET('BlocksFinal (Kyle and Naser)'!$A8,0,(K$1-1)*10,1,3),{2,6,8})/16-$B9)*2/3+(SUMPRODUCT(OFFSET('BlocksFinal (Kyle and Naser)'!$A8,0,(K$1-1)*10+3,1,2),{6,2})/8-$C9)/3 -> -24.106329 | ... AZ9: =(SUMPRODUCT(OFFSET('BlocksFinal (Kyle and Naser)'!$A8,0,(AZ$1-1)*10,1,3),{2,6,8})/16-$B9)*2/3+(SUMPRODUCT(OFFSET('BlocksFinal (Kyle and Naser)'!$A8,0,(AZ$1-1)*10+3,1,2),{6,2})/8-$C9)/3 -> 8.5099963
A10: 44774 | B10: 131.4 | C10: 57.85 | D10: =(SUMPRODUCT(OFFSET('BlocksFinal (Kyle and Naser)'!$A9,0,(D$1-1)*10,1,3),{2,6,8})/16-$B10)*2/3+(SUMPRODUCT(OFFSET('BlocksFinal (Kyle and Naser)'!$A9,0,(D$1-1)*10+3,1,2),{6,2})/8-$C10)/3 -> -62.975213 | E10: =(SUMPRODUCT(OFFSET('BlocksFinal (Kyle and Naser)'!$A9,0,(E$1-1)*10,1,3),{2,6,8})/16-$B10)*2/3+(SUMPRODUCT(OFFSET('BlocksFinal (Kyle and Naser)'!$A9,0,(E$1-1)*10+3,1,2),{6,2})/8-$C10)/3 -> -34.409868 | F10: =(SUMPRODUCT(OFFSET('BlocksFinal (Kyle and Naser)'!$A9,0,(F$1-1)*10,1,3),{2,6,8})/16-$B10)*2/3+(SUMPRODUCT(OFFSET('BlocksFinal (Kyle and Naser)'!$A9,0,(F$1-1)*10+3,1,2),{6,2})/8-$C10)/3 -> -61.471625 | G10: =(SUMPRODUCT(OFFSET('BlocksFinal (Kyle and Naser)'!$A9,0,(G$1-1)*10,1,3),{2,6,8})/16-$B10)*2/3+(SUMPRODUCT(OFFSET('BlocksFinal (Kyle and Naser)'!$A9,0,(G$1-1)*10+3,1,2),{6,2})/8-$C10)/3 -> -39.438131 | H10: =(SUMPRODUCT(OFFSET('BlocksFinal (Kyle and Naser)'!$A9,0,(H$1-1)*10,1,3),{2,6,8})/16-$B10)*2/3+(SUMPRODUCT(OFFSET('BlocksFinal (Kyle and Naser)'!$A9,0,(H$1-1)*10+3,1,2),{6,2})/8-$C10)/3 -> -53.751205 | I10: =(SUMPRODUCT(OFFSET('BlocksFinal (Kyle and Naser)'!$A9,0,(I$1-1)*10,1,3),{2,6,8})/16-$B10)*2/3+(SUMPRODUCT(OFFSET('BlocksFinal (Kyle and Naser)'!$A9,0,(I$1-1)*10+3,1,2),{6,2})/8-$C10)/3 -> -49.010476 | J10: =(SUMPRODUCT(OFFSET('BlocksFinal (Kyle and Naser)'!$A9,0,(J$1-1)*10,1,3),{2,6,8})/16-$B10)*2/3+(SUMPRODUCT(OFFSET('BlocksFinal (Kyle and Naser)'!$A9,0,(J$1-1)*10+3,1,2),{6,2})/8-$C10)/3 -> -52.722827 | K10: =(SUMPRODUCT(OFFSET('BlocksFinal (Kyle and Naser)'!$A9,0,(K$1-1)*10,1,3),{2,6,8})/16-$B10)*2/3+(SUMPRODUCT(OFFSET('BlocksFinal (Kyle and Naser)'!$A9,0,(K$1-1)*10+3,1,2),{6,2})/8-$C10)/3 -> -47.412861 | ... AZ10: =(SUMPRODUCT(OFFSET('BlocksFinal (Kyle and Naser)'!$A9,0,(AZ$1-1)*10,1,3),{2,6,8})/16-$B10)*2/3+(SUMPRODUCT(OFFSET('BlocksFinal (Kyle and Naser)'!$A9,0,(AZ$1-1)*10+3,1,2),{6,2})/8-$C10)/3 -> -61.941629
A11: 44805 | B11: 100.5 | C11: 50.75 | D11: =(SUMPRODUCT(OFFSET('BlocksFinal (Kyle and Naser)'!$A10,0,(D$1-1)*10,1,3),{2,6,8})/16-$B11)*2/3+(SUMPRODUCT(OFFSET('BlocksFinal (Kyle and Naser)'!$A10,0,(D$1-1)*10+3,1,2),{6,2})/8-$C11)/3 -> -4.8156685 | E11: =(SUMPRODUCT(OFFSET('BlocksFinal (Kyle and Naser)'!$A10,0,(E$1-1)*10,1,3),{2,6,8})/16-$B11)*2/3+(SUMPRODUCT(OFFSET('BlocksFinal (Kyle and Naser)'!$A10,0,(E$1-1)*10+3,1,2),{6,2})/8-$C11)/3 -> -15.83899 | F11: =(SUMPRODUCT(OFFSET('BlocksFinal (Kyle and Naser)'!$A10,0,(F$1-1)*10,1,3),{2,6,8})/16-$B11)*2/3+(SUMPRODUCT(OFFSET('BlocksFinal (Kyle and Naser)'!$A10,0,(F$1-1)*10+3,1,2),{6,2})/8-$C11)/3 -> -23.954476 | G11: =(SUMPRODUCT(OFFSET('BlocksFinal (Kyle and Naser)'!$A10,0,(G$1-1)*10,1,3),{2,6,8})/16-$B11)*2/3+(SUMPRODUCT(OFFSET('BlocksFinal (Kyle and Naser)'!$A10,0,(G$1-1)*10+3,1,2),{6,2})/8-$C11)/3 -> -27.887312 | H11: =(SUMPRODUCT(OFFSET('BlocksFinal (Kyle and Naser)'!$A10,0,(H$1-1)*10,1,3),{2,6,8})/16-$B11)*2/3+(SUMPRODUCT(OFFSET('BlocksFinal (Kyle and Naser)'!$A10,0,(H$1-1)*10+3,1,2),{6,2})/8-$C11)/3 -> -21.06711 | I11: =(SUMPRODUCT(OFFSET('BlocksFinal (Kyle and Naser)'!$A10,0,(I$1-1)*10,1,3),{2,6,8})/16-$B11)*2/3+(SUMPRODUCT(OFFSET('BlocksFinal (Kyle and Naser)'!$A10,0,(I$1-1)*10+3,1,2),{6,2})/8-$C11)/3 -> -33.302041 | J11: =(SUMPRODUCT(OFFSET('BlocksFinal (Kyle and Naser)'!$A10,0,(J$1-1)*10,1,3),{2,6,8})/16-$B11)*2/3+(SUMPRODUCT(OFFSET('BlocksFinal (Kyle and Naser)'!$A10,0,(J$1-1)*10+3,1,2),{6,2})/8-$C11)/3 -> -21.431958 | K11: =(SUMPRODUCT(OFFSET('BlocksFinal (Kyle and Naser)'!$A10,0,(K$1-1)*10,1,3),{2,6,8})/16-$B11)*2/3+(SUMPRODUCT(OFFSET('BlocksFinal (Kyle and Naser)'!$A10,0,(K$1-1)*10+3,1,2),{6,2})/8-$C11)/3 -> -15.993739 | ... AZ11: =(SUMPRODUCT(OFFSET('BlocksFinal (Kyle and Naser)'!$A10,0,(AZ$1-1)*10,1,3),{2,6,8})/16-$B11)*2/3+(SUMPRODUCT(OFFSET('BlocksFinal (Kyle and Naser)'!$A10,0,(AZ$1-1)*10+3,1,2),{6,2})/8-$C11)/3 -> -29.252608
A12: 44835 | B12: 57.9 | C12: 52.75 | D12: =(SUMPRODUCT(OFFSET('BlocksFinal (Kyle and Naser)'!$A11,0,(D$1-1)*10,1,3),{2,6,8})/16-$B12)*2/3+(SUMPRODUCT(OFFSET('BlocksFinal (Kyle and Naser)'!$A11,0,(D$1-1)*10+3,1,2),{6,2})/8-$C12)/3 -> -22.363924 | E12: =(SUMPRODUCT(OFFSET('BlocksFinal (Kyle and Naser)'!$A11,0,(E$1-1)*10,1,3),{2,6,8})/16-$B12)*2/3+(SUMPRODUCT(OFFSET('BlocksFinal (Kyle and Naser)'!$A11,0,(E$1-1)*10+3,1,2),{6,2})/8-$C12)/3 -> 3.9945139 | F12: =(SUMPRODUCT(OFFSET('BlocksFinal (Kyle and Naser)'!$A11,0,(F$1-1)*10,1,3),{2,6,8})/16-$B12)*2/3+(SUMPRODUCT(OFFSET('BlocksFinal (Kyle and Naser)'!$A11,0,(F$1-1)*10+3,1,2),{6,2})/8-$C12)/3 -> -7.0312307 | G12: =(SUMPRODUCT(OFFSET('BlocksFinal (Kyle and Naser)'!$A11,0,(G$1-1)*10,1,3),{2,6,8})/16-$B12)*2/3+(SUMPRODUCT(OFFSET('BlocksFinal (Kyle and Naser)'!$A11,0,(G$1-1)*10+3,1,2),{6,2})/8-$C12)/3 -> 9.3964183 | H12: =(SUMPRODUCT(OFFSET('BlocksFinal (Kyle and Naser)'!$A11,0,(H$1-1)*10,1,3),{2,6,8})/16-$B12)*2/3+(SUMPRODUCT(OFFSET('BlocksFinal (Kyle and Naser)'!$A11,0,(H$1-1)*10+3,1,2),{6,2})/8-$C12)/3 -> -3.6376098 | I12: =(SUMPRODUCT(OFFSET('BlocksFinal (Kyle and Naser)'!$A11,0,(I$1-1)*10,1,3),{2,6,8})/16-$B12)*2/3+(SUMPRODUCT(OFFSET('BlocksFinal (Kyle and Naser)'!$A11,0,(I$1-1)*10+3,1,2),{6,2})/8-$C12)/3 -> -1.4553214 | J12: =(SUMPRODUCT(OFFSET('BlocksFinal (Kyle and Naser)'!$A11,0,(J$1-1)*10,1,3),{2,6,8})/16-$B12)*2/3+(SUMPRODUCT(OFFSET('BlocksFinal (Kyle and Naser)'!$A11,0,(J$1-1)*10+3,1,2),{6,2})/8-$C12)/3 -> -10.618538 | K12: =(SUMPRODUCT(OFFSET('BlocksFinal (Kyle and Naser)'!$A11,0,(K$1-1)*10,1,3),{2,6,8})/16-$B12)*2/3+(SUMPRODUCT(OFFSET('BlocksFinal (Kyle and Naser)'!$A11,0,(K$1-1)*10+3,1,2),{6,2})/8-$C12)/3 -> -9.5999244 | ... AZ12: =(SUMPRODUCT(OFFSET('BlocksFinal (Kyle and Naser)'!$A11,0,(AZ$1-1)*10,1,3),{2,6,8})/16-$B12)*2/3+(SUMPRODUCT(OFFSET('BlocksFinal (Kyle and Naser)'!$A11,0,(AZ$1-1)*10+3,1,2),{6,2})/8-$C12)/3 -> 3.9970145
A13: 44866 | B13: 54.65 | C13: 48.65 | D13: =(SUMPRODUCT(OFFSET('BlocksFinal (Kyle and Naser)'!$A12,0,(D$1-1)*10,1,3),{2,6,8})/16-$B13)*2/3+(SUMPRODUCT(OFFSET('BlocksFinal (Kyle and Naser)'!$A12,0,(D$1-1)*10+3,1,2),{6,2})/8-$C13)/3 -> 21.92002 | E13: =(SUMPRODUCT(OFFSET('BlocksFinal (Kyle and Naser)'!$A12,0,(E$1-1)*10,1,3),{2,6,8})/16-$B13)*2/3+(SUMPRODUCT(OFFSET('BlocksFinal (Kyle and Naser)'!$A12,0,(E$1-1)*10+3,1,2),{6,2})/8-$C13)/3 -> -18.061285 | F13: =(SUMPRODUCT(OFFSET('BlocksFinal (Kyle and Naser)'!$A12,0,(F$1-1)*10,1,3),{2,6,8})/16-$B13)*2/3+(SUMPRODUCT(OFFSET('BlocksFinal (Kyle and Naser)'!$A12,0,(F$1-1)*10+3,1,2),{6,2})/8-$C13)/3 -> 28.693449 | G13: =(SUMPRODUCT(OFFSET('BlocksFinal (Kyle and Naser)'!$A12,0,(G$1-1)*10,1,3),{2,6,8})/16-$B13)*2/3+(SUMPRODUCT(OFFSET('BlocksFinal (Kyle and Naser)'!$A12,0,(G$1-1)*10+3,1,2),{6,2})/8-$C13)/3 -> 15.600086 | H13: =(SUMPRODUCT(OFFSET('BlocksFinal (Kyle and Naser)'!$A12,0,(H$1-1)*10,1,3),{2,6,8})/16-$B13)*2/3+(SUMPRODUCT(OFFSET('BlocksFinal (Kyle and Naser)'!$A12,0,(H$1-1)*10+3,1,2),{6,2})/8-$C13)/3 -> 25.01128 | I13: =(SUMPRODUCT(OFFSET('BlocksFinal (Kyle and Naser)'!$A12,0,(I$1-1)*10,1,3),{2,6,8})/16-$B13)*2/3+(SUMPRODUCT(OFFSET('BlocksFinal (Kyle and Naser)'!$A12,0,(I$1-1)*10+3,1,2),{6,2})/8-$C13)/3 -> -0.48174545 | J13: =(SUMPRODUCT(OFFSET('BlocksFinal (Kyle and Naser)'!$A12,0,(J$1-1)*10,1,3),{2,6,8})/16-$B13)*2/3+(SUMPRODUCT(OFFSET('BlocksFinal (Kyle and Naser)'!$A12,0,(J$1-1)*10+3,1,2),{6,2})/8-$C13)/3 -> 13.876844 | K13: =(SUMPRODUCT(OFFSET('BlocksFinal (Kyle and Naser)'!$A12,0,(K$1-1)*10,1,3),{2,6,8})/16-$B13)*2/3+(SUMPRODUCT(OFFSET('BlocksFinal (Kyle and Naser)'!$A12,0,(K$1-1)*10+3,1,2),{6,2})/8-$C13)/3 -> -4.3950376 | ... AZ13: =(SUMPRODUCT(OFFSET('BlocksFinal (Kyle and Naser)'!$A12,0,(AZ$1-1)*10,1,3),{2,6,8})/16-$B13)*2/3+(SUMPRODUCT(OFFSET('BlocksFinal (Kyle and Naser)'!$A12,0,(AZ$1-1)*10+3,1,2),{6,2})/8-$C13)/3 -> -16.098215
... A61: 46327 | B61: 50.35 | C61: 47.05 | D61: =(SUMPRODUCT(OFFSET('BlocksFinal (Kyle and Naser)'!$A60,0,(D$1-1)*10,1,3),{2,6,8})/16-$B61)*2/3+(SUMPRODUCT(OFFSET('BlocksFinal (Kyle and Naser)'!$A60,0,(D$1-1)*10+3,1,2),{6,2})/8-$C61)/3 -> -4.1943938 | E61: =(SUMPRODUCT(OFFSET('BlocksFinal (Kyle and Naser)'!$A60,0,(E$1-1)*10,1,3),{2,6,8})/16-$B61)*2/3+(SUMPRODUCT(OFFSET('BlocksFinal (Kyle and Naser)'!$A60,0,(E$1-1)*10+3,1,2),{6,2})/8-$C61)/3 -> -16.257974 | F61: =(SUMPRODUCT(OFFSET('BlocksFinal (Kyle and Naser)'!$A60,0,(F$1-1)*10,1,3),{2,6,8})/16-$B61)*2/3+(SUMPRODUCT(OFFSET('BlocksFinal (Kyle and Naser)'!$A60,0,(F$1-1)*10+3,1,2),{6,2})/8-$C61)/3 -> -6.288748 | G61: =(SUMPRODUCT(OFFSET('BlocksFinal (Kyle and Naser)'!$A60,0,(G$1-1)*10,1,3),{2,6,8})/16-$B61)*2/3+(SUMPRODUCT(OFFSET('BlocksFinal (Kyle and Naser)'!$A60,0,(G$1-1)*10+3,1,2),{6,2})/8-$C61)/3 -> -5.252931 | H61: =(SUMPRODUCT(OFFSET('BlocksFinal (Kyle and Naser)'!$A60,0,(H$1-1)*10,1,3),{2,6,8})/16-$B61)*2/3+(SUMPRODUCT(OFFSET('BlocksFinal (Kyle and Naser)'!$A60,0,(H$1-1)*10+3,1,2),{6,2})/8-$C61)/3 -> -2.8137625 | I61: =(SUMPRODUCT(OFFSET('BlocksFinal (Kyle and Naser)'!$A60,0,(I$1-1)*10,1,3),{2,6,8})/16-$B61)*2/3+(SUMPRODUCT(OFFSET('BlocksFinal (Kyle and Naser)'!$A60,0,(I$1-1)*10+3,1,2),{6,2})/8-$C61)/3 -> -22.141038 | J61: =(SUMPRODUCT(OFFSET('BlocksFinal (Kyle and Naser)'!$A60,0,(J$1-1)*10,1,3),{2,6,8})/16-$B61)*2/3+(SUMPRODUCT(OFFSET('BlocksFinal (Kyle and Naser)'!$A60,0,(J$1-1)*10+3,1,2),{6,2})/8-$C61)/3 -> -14.663588 | K61: =(SUMPRODUCT(OFFSET('BlocksFinal (Kyle and Naser)'!$A60,0,(K$1-1)*10,1,3),{2,6,8})/16-$B61)*2/3+(SUMPRODUCT(OFFSET('BlocksFinal (Kyle and Naser)'!$A60,0,(K$1-1)*10+3,1,2),{6,2})/8-$C61)/3 -> 7.3925167 | ... AZ61: =(SUMPRODUCT(OFFSET('BlocksFinal (Kyle and Naser)'!$A60,0,(AZ$1-1)*10,1,3),{2,6,8})/16-$B61)*2/3+(SUMPRODUCT(OFFSET('BlocksFinal (Kyle and Naser)'!$A60,0,(AZ$1-1)*10+3,1,2),{6,2})/8-$C61)/3 -> 3.2449413

Sheet Energy diff
A1: Date | B1: num of days | C1: 1 | D1: 2 | E1: 3 | F1: 4 | G1: 5 | H1: 6 | I1: 7 | J1: 8 | K1: 9 | L1: 10 | M1: 11 | N1: 12 | O1: 13 | P1: 14 | Q1: 15 | R1: 16 | S1: 17 | T1: 18 | U1: 19 | V1: 20 | W1: 21 | X1: 22 | Y1: 23 | Z1: 24 | AA1: 25 | AB1: 26 | AC1: 27 | AD1: 28 | AE1: 29 | AF1: 30 | AG1: 31 | AH1: 32 | AI1: 33 | AJ1: 34 | AK1: 35 | AL1: 36 | AM1: 37 | AN1: 38 | AO1: 39 | AP1: 40 | AQ1: 41 | AR1: 42 | AS1: 43 | AT1: 44 | AU1: 45 | AV1: 46 | AW1: 47 | AX1: 48 | AY1: 49
A2: 44531 | B2: =A3-A2 -> 31 | C2: =(SUMPRODUCT(OFFSET('BlocksFinal (Kyle and Naser)'!$A1,0,(C$1-1)*10+5,1,5),{2,6,8,6,2}))*$B2/1000-'Sys Redisual Energy H16'!D1-'Sys Redisual Energy L08'!D1 -> -537.82471 | D2: =(SUMPRODUCT(OFFSET('BlocksFinal (Kyle and Naser)'!$A1,0,(D$1-1)*10+5,1,5),{2,6,8,6,2}))*$B2/1000-'Sys Redisual Energy H16'!E1-'Sys Redisual Energy L08'!E1 -> 88.412996 | E2: =(SUMPRODUCT(OFFSET('BlocksFinal (Kyle and Naser)'!$A1,0,(E$1-1)*10+5,1,5),{2,6,8,6,2}))*$B2/1000-'Sys Redisual Energy H16'!F1-'Sys Redisual Energy L08'!F1 -> -426.06018 | F2: =(SUMPRODUCT(OFFSET('BlocksFinal (Kyle and Naser)'!$A1,0,(F$1-1)*10+5,1,5),{2,6,8,6,2}))*$B2/1000-'Sys Redisual Energy H16'!G1-'Sys Redisual Energy L08'!G1 -> 145.72497 | G2: =(SUMPRODUCT(OFFSET('BlocksFinal (Kyle and Naser)'!$A1,0,(G$1-1)*10+5,1,5),{2,6,8,6,2}))*$B2/1000-'Sys Redisual Energy H16'!H1-'Sys Redisual Energy L08'!H1 -> 631.94886 | H2: =(SUMPRODUCT(OFFSET('BlocksFinal (Kyle and Naser)'!$A1,0,(H$1-1)*10+5,1,5),{2,6,8,6,2}))*$B2/1000-'Sys Redisual Energy H16'!I1-'Sys Redisual Energy L08'!I1 -> 459.08378 | I2: =(SUMPRODUCT(OFFSET('BlocksFinal (Kyle and Naser)'!$A1,0,(I$1-1)*10+5,1,5),{2,6,8,6,2}))*$B2/1000-'Sys Redisual Energy H16'!J1-'Sys Redisual Energy L08'!J1 -> -374.47353 | J2: =(SUMPRODUCT(OFFSET('BlocksFinal (Kyle and Naser)'!$A1,0,(J$1-1)*10+5,1,5),{2,6,8,6,2}))*$B2/1000-'Sys Redisual Energy H16'!K1-'Sys Redisual Energy L08'!K1 -> -91.805552 | ... AY2: =(SUMPRODUCT(OFFSET('BlocksFinal (Kyle and Naser)'!$A1,0,(AY$1-1)*10+5,1,5),{2,6,8,6,2}))*$B2/1000-'Sys Redisual Energy H16'!AZ1-'Sys Redisual Energy L08'!AZ1 -> 408.08695
A3: 44562 | B3: =A4-A3 -> 31 | C3: =(SUMPRODUCT(OFFSET('BlocksFinal (Kyle and Naser)'!$A2,0,(C$1-1)*10+5,1,5),{2,6,8,6,2}))*$B3/1000-'Sys Redisual Energy H16'!D2-'Sys Redisual Energy L08'!D2 -> -126.48931 | D3: =(SUMPRODUCT(OFFSET('BlocksFinal (Kyle and Naser)'!$A2,0,(D$1-1)*10+5,1,5),{2,6,8,6,2}))*$B3/1000-'Sys Redisual Energy H16'!E2-'Sys Redisual Energy L08'!E2 -> 6.7919478 | E3: =(SUMPRODUCT(OFFSET('BlocksFinal (Kyle and Naser)'!$A2,0,(E$1-1)*10+5,1,5),{2,6,8,6,2}))*$B3/1000-'Sys Redisual Energy H16'!F2-'Sys Redisual Energy L08'!F2 -> -275.59083 | F3: =(SUMPRODUCT(OFFSET('BlocksFinal (Kyle and Naser)'!$A2,0,(F$1-1)*10+5,1,5),{2,6,8,6,2}))*$B3/1000-'Sys Redisual Energy H16'!G2-'Sys Redisual Energy L08'!G2 -> 606.08988 | G3: =(SUMPRODUCT(OFFSET('BlocksFinal (Kyle and Naser)'!$A2,0,(G$1-1)*10+5,1,5),{2,6,8,6,2}))*$B3/1000-'Sys Redisual Energy H16'!H2-'Sys Redisual Energy L08'!H2 -> 432.31358 | H3: =(SUMPRODUCT(OFFSET('BlocksFinal (Kyle and Naser)'!$A2,0,(H$1-1)*10+5,1,5),{2,6,8,6,2}))*$B3/1000-'Sys Redisual Energy H16'!I2-'Sys Redisual Energy L08'!I2 -> -593.96674 | I3: =(SUMPRODUCT(OFFSET('BlocksFinal (Kyle and Naser)'!$A2,0,(I$1-1)*10+5,1,5),{2,6,8,6,2}))*$B3/1000-'Sys Redisual Energy H16'!J2-'Sys Redisual Energy L08'!J2 -> -1850.1787 | J3: =(SUMPRODUCT(OFFSET('BlocksFinal (Kyle and Naser)'!$A2,0,(J$1-1)*10+5,1,5),{2,6,8,6,2}))*$B3/1000-'Sys Redisual Energy H16'!K2-'Sys Redisual Energy L08'!K2 -> -470.15363 | ... AY3: =(SUMPRODUCT(OFFSET('BlocksFinal (Kyle and Naser)'!$A2,0,(AY$1-1)*10+5,1,5),{2,6,8,6,2}))*$B3/1000-'Sys Redisual Energy H16'!AZ2-'Sys Redisual Energy L08'!AZ2 -> -1164.2259
A4: 44593 | B4: =A5-A4 -> 28 | C4: =(SUMPRODUCT(OFFSET('BlocksFinal (Kyle and Naser)'!$A3,0,(C$1-1)*10+5,1,5),{2,6,8,6,2}))*$B4/1000-'Sys Redisual Energy H16'!D3-'Sys Redisual Energy L08'!D3 -> -497.63284 | D4: =(SUMPRODUCT(OFFSET('BlocksFinal (Kyle and Naser)'!$A3,0,(D$1-1)*10+5,1,5),{2,6,8,6,2}))*$B4/1000-'Sys Redisual Energy H16'!E3-'Sys Redisual Energy L08'!E3 -> 450.84847 | E4: =(SUMPRODUCT(OFFSET('BlocksFinal (Kyle and Naser)'!$A3,0,(E$1-1)*10+5,1,5),{2,6,8,6,2}))*$B4/1000-'Sys Redisual Energy H16'!F3-'Sys Redisual Energy L08'!F3 -> -99.693206 | F4: =(SUMPRODUCT(OFFSET('BlocksFinal (Kyle and Naser)'!$A3,0,(F$1-1)*10+5,1,5),{2,6,8,6,2}))*$B4/1000-'Sys Redisual Energy H16'!G3-'Sys Redisual Energy L08'!G3 -> 934.70855 | G4: =(SUMPRODUCT(OFFSET('BlocksFinal (Kyle and Naser)'!$A3,0,(G$1-1)*10+5,1,5),{2,6,8,6,2}))*$B4/1000-'Sys Redisual Energy H16'!H3-'Sys Redisual Energy L08'!H3 -> 211.22835 | H4: =(SUMPRODUCT(OFFSET('BlocksFinal (Kyle and Naser)'!$A3,0,(H$1-1)*10+5,1,5),{2,6,8,6,2}))*$B4/1000-'Sys Redisual Energy H16'!I3-'Sys Redisual Energy L08'!I3 -> -11.947371 | I4: =(SUMPRODUCT(OFFSET('BlocksFinal (Kyle and Naser)'!$A3,0,(I$1-1)*10+5,1,5),{2,6,8,6,2}))*$B4/1000-'Sys Redisual Energy H16'!J3-'Sys Redisual Energy L08'!J3 -> -16.870887 | J4: =(SUMPRODUCT(OFFSET('BlocksFinal (Kyle and Naser)'!$A3,0,(J$1-1)*10+5,1,5),{2,6,8,6,2}))*$B4/1000-'Sys Redisual Energy H16'!K3-'Sys Redisual Energy L08'!K3 -> 556.43013 | ... AY4: =(SUMPRODUCT(OFFSET('BlocksFinal (Kyle and Naser)'!$A3,0,(AY$1-1)*10+5,1,5),{2,6,8,6,2}))*$B4/1000-'Sys Redisual Energy H16'!AZ3-'Sys Redisual Energy L08'!AZ3 -> -82.290417
A5: 44621 | B5: =A6-A5 -> 31 | C5: =(SUMPRODUCT(OFFSET('BlocksFinal (Kyle and Naser)'!$A4,0,(C$1-1)*10+5,1,5),{2,6,8,6,2}))*$B5/1000-'Sys Redisual Energy H16'!D4-'Sys Redisual Energy L08'!D4 -> 727.33902 | D5: =(SUMPRODUCT(OFFSET('BlocksFinal (Kyle and Naser)'!$A4,0,(D$1-1)*10+5,1,5),{2,6,8,6,2}))*$B5/1000-'Sys Redisual Energy H16'!E4-'Sys Redisual Energy L08'!E4 -> 1100.0321 | E5: =(SUMPRODUCT(OFFSET('BlocksFinal (Kyle and Naser)'!$A4,0,(E$1-1)*10+5,1,5),{2,6,8,6,2}))*$B5/1000-'Sys Redisual Energy H16'!F4-'Sys Redisual Energy L08'!F4 -> 1137.0579 | F5: =(SUMPRODUCT(OFFSET('BlocksFinal (Kyle and Naser)'!$A4,0,(F$1-1)*10+5,1,5),{2,6,8,6,2}))*$B5/1000-'Sys Redisual Energy H16'!G4-'Sys Redisual Energy L08'!G4 -> 453.26782 | G5: =(SUMPRODUCT(OFFSET('BlocksFinal (Kyle and Naser)'!$A4,0,(G$1-1)*10+5,1,5),{2,6,8,6,2}))*$B5/1000-'Sys Redisual Energy H16'!H4-'Sys Redisual Energy L08'!H4 -> -186.92541 | H5: =(SUMPRODUCT(OFFSET('BlocksFinal (Kyle and Naser)'!$A4,0,(H$1-1)*10+5,1,5),{2,6,8,6,2}))*$B5/1000-'Sys Redisual Energy H16'!I4-'Sys Redisual Energy L08'!I4 -> 1014.433 | I5: =(SUMPRODUCT(OFFSET('BlocksFinal (Kyle and Naser)'!$A4,0,(I$1-1)*10+5,1,5),{2,6,8,6,2}))*$B5/1000-'Sys Redisual Energy H16'!J4-'Sys Redisual Energy L08'!J4 -> 680.78481 | J5: =(SUMPRODUCT(OFFSET('BlocksFinal (Kyle and Naser)'!$A4,0,(J$1-1)*10+5,1,5),{2,6,8,6,2}))*$B5/1000-'Sys Redisual Energy H16'!K4-'Sys Redisual Energy L08'!K4 -> 1420.7984 | ... AY5: =(SUMPRODUCT(OFFSET('BlocksFinal (Kyle and Naser)'!$A4,0,(AY$1-1)*10+5,1,5),{2,6,8,6,2}))*$B5/1000-'Sys Redisual Energy H16'!AZ4-'Sys Redisual Energy L08'!AZ4 -> 211.23515
A6: 44652 | B6: =A7-A6 -> 30 | C6: =(SUMPRODUCT(OFFSET('BlocksFinal (Kyle and Naser)'!$A5,0,(C$1-1)*10+5,1,5),{2,6,8,6,2}))*$B6/1000-'Sys Redisual Energy H16'!D5-'Sys Redisual Energy L08'!D5 -> 861.27611 | D6: =(SUMPRODUCT(OFFSET('BlocksFinal (Kyle and Naser)'!$A5,0,(D$1-1)*10+5,1,5),{2,6,8,6,2}))*$B6/1000-'Sys Redisual Energy H16'!E5-'Sys Redisual Energy L08'!E5 -> 2485.4404 | E6: =(SUMPRODUCT(OFFSET('BlocksFinal (Kyle and Naser)'!$A5,0,(E$1-1)*10+5,1,5),{2,6,8,6,2}))*$B6/1000-'Sys Redisual Energy H16'!F5-'Sys Redisual Energy L08'!F5 -> 1157.8028 | F6: =(SUMPRODUCT(OFFSET('BlocksFinal (Kyle and Naser)'!$A5,0,(F$1-1)*10+5,1,5),{2,6,8,6,2}))*$B6/1000-'Sys Redisual Energy H16'!G5-'Sys Redisual Energy L08'!G5 -> 861.99724 | G6: =(SUMPRODUCT(OFFSET('BlocksFinal (Kyle and Naser)'!$A5,0,(G$1-1)*10+5,1,5),{2,6,8,6,2}))*$B6/1000-'Sys Redisual Energy H16'!H5-'Sys Redisual Energy L08'!H5 -> 798.40335 | H6: =(SUMPRODUCT(OFFSET('BlocksFinal (Kyle and Naser)'!$A5,0,(H$1-1)*10+5,1,5),{2,6,8,6,2}))*$B6/1000-'Sys Redisual Energy H16'!I5-'Sys Redisual Energy L08'!I5 -> 1732.4048 | I6: =(SUMPRODUCT(OFFSET('BlocksFinal (Kyle and Naser)'!$A5,0,(I$1-1)*10+5,1,5),{2,6,8,6,2}))*$B6/1000-'Sys Redisual Energy H16'!J5-'Sys Redisual Energy L08'!J5 -> 1828.5248 | J6: =(SUMPRODUCT(OFFSET('BlocksFinal (Kyle and Naser)'!$A5,0,(J$1-1)*10+5,1,5),{2,6,8,6,2}))*$B6/1000-'Sys Redisual Energy H16'!K5-'Sys Redisual Energy L08'!K5 -> 2160.4862 | ... AY6: =(SUMPRODUCT(OFFSET('BlocksFinal (Kyle and Naser)'!$A5,0,(AY$1-1)*10+5,1,5),{2,6,8,6,2}))*$B6/1000-'Sys Redisual Energy H16'!AZ5-'Sys Redisual Energy L08'!AZ5 -> 1302.564
A7: 44682 | B7: =A8-A7 -> 31 | C7: =(SUMPRODUCT(OFFSET('BlocksFinal (Kyle and Naser)'!$A6,0,(C$1-1)*10+5,1,5),{2,6,8,6,2}))*$B7/1000-'Sys Redisual Energy H16'!D6-'Sys Redisual Energy L08'!D6 -> 1490.1982 | D7: =(SUMPRODUCT(OFFSET('BlocksFinal (Kyle and Naser)'!$A6,0,(D$1-1)*10+5,1,5),{2,6,8,6,2}))*$B7/1000-'Sys Redisual Energy H16'!E6-'Sys Redisual Energy L08'!E6 -> 2132.5792 | E7: =(SUMPRODUCT(OFFSET('BlocksFinal (Kyle and Naser)'!$A6,0,(E$1-1)*10+5,1,5),{2,6,8,6,2}))*$B7/1000-'Sys Redisual Energy H16'!F6-'Sys Redisual Energy L08'!F6 -> 1510.8975 | F7: =(SUMPRODUCT(OFFSET('BlocksFinal (Kyle and Naser)'!$A6,0,(F$1-1)*10+5,1,5),{2,6,8,6,2}))*$B7/1000-'Sys Redisual Energy H16'!G6-'Sys Redisual Energy L08'!G6 -> 2652.4091 | G7: =(SUMPRODUCT(OFFSET('BlocksFinal (Kyle and Naser)'!$A6,0,(G$1-1)*10+5,1,5),{2,6,8,6,2}))*$B7/1000-'Sys Redisual Energy H16'!H6-'Sys Redisual Energy L08'!H6 -> 1695.6216 | H7: =(SUMPRODUCT(OFFSET('BlocksFinal (Kyle and Naser)'!$A6,0,(H$1-1)*10+5,1,5),{2,6,8,6,2}))*$B7/1000-'Sys Redisual Energy H16'!I6-'Sys Redisual Energy L08'!I6 -> 3131.7668 | I7: =(SUMPRODUCT(OFFSET('BlocksFinal (Kyle and Naser)'!$A6,0,(I$1-1)*10+5,1,5),{2,6,8,6,2}))*$B7/1000-'Sys Redisual Energy H16'!J6-'Sys Redisual Energy L08'!J6 -> 2946.3463 | J7: =(SUMPRODUCT(OFFSET('BlocksFinal (Kyle and Naser)'!$A6,0,(J$1-1)*10+5,1,5),{2,6,8,6,2}))*$B7/1000-'Sys Redisual Energy H16'!K6-'Sys Redisual Energy L08'!K6 -> 1319.0615 | ... AY7: =(SUMPRODUCT(OFFSET('BlocksFinal (Kyle and Naser)'!$A6,0,(AY$1-1)*10+5,1,5),{2,6,8,6,2}))*$B7/1000-'Sys Redisual Energy H16'!AZ6-'Sys Redisual Energy L08'!AZ6 -> 2428.5486
A8: 44713 | B8: =A9-A8 -> 30 | C8: =(SUMPRODUCT(OFFSET('BlocksFinal (Kyle and Naser)'!$A7,0,(C$1-1)*10+5,1,5),{2,6,8,6,2}))*$B8/1000-'Sys Redisual Energy H16'!D7-'Sys Redisual Energy L08'!D7 -> 3111.8409 | D8: =(SUMPRODUCT(OFFSET('BlocksFinal (Kyle and Naser)'!$A7,0,(D$1-1)*10+5,1,5),{2,6,8,6,2}))*$B8/1000-'Sys Redisual Energy H16'!E7-'Sys Redisual Energy L08'!E7 -> 2012.1588 | E8: =(SUMPRODUCT(OFFSET('BlocksFinal (Kyle and Naser)'!$A7,0,(E$1-1)*10+5,1,5),{2,6,8,6,2}))*$B8/1000-'Sys Redisual Energy H16'!F7-'Sys Redisual Energy L08'!F7 -> 3404.7718 | F8: =(SUMPRODUCT(OFFSET('BlocksFinal (Kyle and Naser)'!$A7,0,(F$1-1)*10+5,1,5),{2,6,8,6,2}))*$B8/1000-'Sys Redisual Energy H16'!G7-'Sys Redisual Energy L08'!G7 -> 3167.3048 | G8: =(SUMPRODUCT(OFFSET('BlocksFinal (Kyle and Naser)'!$A7,0,(G$1-1)*10+5,1,5),{2,6,8,6,2}))*$B8/1000-'Sys Redisual Energy H16'!H7-'Sys Redisual Energy L08'!H7 -> 3019.5234 | H8: =(SUMPRODUCT(OFFSET('BlocksFinal (Kyle and Naser)'!$A7,0,(H$1-1)*10+5,1,5),{2,6,8,6,2}))*$B8/1000-'Sys Redisual Energy H16'!I7-'Sys Redisual Energy L08'!I7 -> 3455.8677 | I8: =(SUMPRODUCT(OFFSET('BlocksFinal (Kyle and Naser)'!$A7,0,(I$1-1)*10+5,1,5),{2,6,8,6,2}))*$B8/1000-'Sys Redisual Energy H16'!J7-'Sys Redisual Energy L08'!J7 -> 2031.5532 | J8: =(SUMPRODUCT(OFFSET('BlocksFinal (Kyle and Naser)'!$A7,0,(J$1-1)*10+5,1,5),{2,6,8,6,2}))*$B8/1000-'Sys Redisual Energy H16'!K7-'Sys Redisual Energy L08'!K7 -> 3288.7546 | ... AY8: =(SUMPRODUCT(OFFSET('BlocksFinal (Kyle and Naser)'!$A7,0,(AY$1-1)*10+5,1,5),{2,6,8,6,2}))*$B8/1000-'Sys Redisual Energy H16'!AZ7-'Sys Redisual Energy L08'!AZ7 -> 2108.5201
A9: 44743 | B9: =A10-A9 -> 31 | C9: =(SUMPRODUCT(OFFSET('BlocksFinal (Kyle and Naser)'!$A8,0,(C$1-1)*10+5,1,5),{2,6,8,6,2}))*$B9/1000-'Sys Redisual Energy H16'!D8-'Sys Redisual Energy L08'!D8 -> 2149.5094 | D9: =(SUMPRODUCT(OFFSET('BlocksFinal (Kyle and Naser)'!$A8,0,(D$1-1)*10+5,1,5),{2,6,8,6,2}))*$B9/1000-'Sys Redisual Energy H16'!E8-'Sys Redisual Energy L08'!E8 -> 3549.5393 | E9: =(SUMPRODUCT(OFFSET('BlocksFinal (Kyle and Naser)'!$A8,0,(E$1-1)*10+5,1,5),{2,6,8,6,2}))*$B9/1000-'Sys Redisual Energy H16'!F8-'Sys Redisual Energy L08'!F8 -> 3432.6588 | F9: =(SUMPRODUCT(OFFSET('BlocksFinal (Kyle and Naser)'!$A8,0,(F$1-1)*10+5,1,5),{2,6,8,6,2}))*$B9/1000-'Sys Redisual Energy H16'!G8-'Sys Redisual Energy L08'!G8 -> 3636.3485 | G9: =(SUMPRODUCT(OFFSET('BlocksFinal (Kyle and Naser)'!$A8,0,(G$1-1)*10+5,1,5),{2,6,8,6,2}))*$B9/1000-'Sys Redisual Energy H16'!H8-'Sys Redisual Energy L08'!H8 -> 2763.0025 | H9: =(SUMPRODUCT(OFFSET('BlocksFinal (Kyle and Naser)'!$A8,0,(H$1-1)*10+5,1,5),{2,6,8,6,2}))*$B9/1000-'Sys Redisual Energy H16'!I8-'Sys Redisual Energy L08'!I8 -> 1883.1438 | I9: =(SUMPRODUCT(OFFSET('BlocksFinal (Kyle and Naser)'!$A8,0,(I$1-1)*10+5,1,5),{2,6,8,6,2}))*$B9/1000-'Sys Redisual Energy H16'!J8-'Sys Redisual Energy L08'!J8 -> 2733.7119 | J9: =(SUMPRODUCT(OFFSET('BlocksFinal (Kyle and Naser)'!$A8,0,(J$1-1)*10+5,1,5),{2,6,8,6,2}))*$B9/1000-'Sys Redisual Energy H16'!K8-'Sys Redisual Energy L08'!K8 -> 2210.2955 | ... AY9: =(SUMPRODUCT(OFFSET('BlocksFinal (Kyle and Naser)'!$A8,0,(AY$1-1)*10+5,1,5),{2,6,8,6,2}))*$B9/1000-'Sys Redisual Energy H16'!AZ8-'Sys Redisual Energy L08'!AZ8 -> 2950.0578
A10: 44774 | B10: =A11-A10 -> 31 | C10: =(SUMPRODUCT(OFFSET('BlocksFinal (Kyle and Naser)'!$A9,0,(C$1-1)*10+5,1,5),{2,6,8,6,2}))*$B10/1000-'Sys Redisual Energy H16'!D9-'Sys Redisual Energy L08'!D9 -> 2543.3864 | D10: =(SUMPRODUCT(OFFSET('BlocksFinal (Kyle and Naser)'!$A9,0,(D$1-1)*10+5,1,5),{2,6,8,6,2}))*$B10/1000-'Sys Redisual Energy H16'!E9-'Sys Redisual Energy L08'!E9 -> 2424.9242 | E10: =(SUMPRODUCT(OFFSET('BlocksFinal (Kyle and Naser)'!$A9,0,(E$1-1)*10+5,1,5),{2,6,8,6,2}))*$B10/1000-'Sys Redisual Energy H16'!F9-'Sys Redisual Energy L08'!F9 -> 3338.7344 | F10: =(SUMPRODUCT(OFFSET('BlocksFinal (Kyle and Naser)'!$A9,0,(F$1-1)*10+5,1,5),{2,6,8,6,2}))*$B10/1000-'Sys Redisual Energy H16'!G9-'Sys Redisual Energy L08'!G9 -> 2823.1188 | G10: =(SUMPRODUCT(OFFSET('BlocksFinal (Kyle and Naser)'!$A9,0,(G$1-1)*10+5,1,5),{2,6,8,6,2}))*$B10/1000-'Sys Redisual Energy H16'!H9-'Sys Redisual Energy L08'!H9 -> 1633.5784 | H10: =(SUMPRODUCT(OFFSET('BlocksFinal (Kyle and Naser)'!$A9,0,(H$1-1)*10+5,1,5),{2,6,8,6,2}))*$B10/1000-'Sys Redisual Energy H16'!I9-'Sys Redisual Energy L08'!I9 -> 2450.0857 | I10: =(SUMPRODUCT(OFFSET('BlocksFinal (Kyle and Naser)'!$A9,0,(I$1-1)*10+5,1,5),{2,6,8,6,2}))*$B10/1000-'Sys Redisual Energy H16'!J9-'Sys Redisual Energy L08'!J9 -> 1564.1937 | J10: =(SUMPRODUCT(OFFSET('BlocksFinal (Kyle and Naser)'!$A9,0,(J$1-1)*10+5,1,5),{2,6,8,6,2}))*$B10/1000-'Sys Redisual Energy H16'!K9-'Sys Redisual Energy L08'!K9 -> 1898.5206 | ... AY10: =(SUMPRODUCT(OFFSET('BlocksFinal (Kyle and Naser)'!$A9,0,(AY$1-1)*10+5,1,5),{2,6,8,6,2}))*$B10/1000-'Sys Redisual Energy H16'!AZ9-'Sys Redisual Energy L08'!AZ9 -> 1439.9552
A11: 44805 | B11: =A12-A11 -> 30 | C11: =(SUMPRODUCT(OFFSET('BlocksFinal (Kyle and Naser)'!$A10,0,(C$1-1)*10+5,1,5),{2,6,8,6,2}))*$B11/1000-'Sys Redisual Energy H16'!D10-'Sys Redisual Energy L08'!D10 -> 1805.8018 | D11: =(SUMPRODUCT(OFFSET('BlocksFinal (Kyle and Naser)'!$A10,0,(D$1-1)*10+5,1,5),{2,6,8,6,2}))*$B11/1000-'Sys Redisual Energy H16'!E10-'Sys Redisual Energy L08'!E10 -> 2889.1172 | E11: =(SUMPRODUCT(OFFSET('BlocksFinal (Kyle and Naser)'!$A10,0,(E$1-1)*10+5,1,5),{2,6,8,6,2}))*$B11/1000-'Sys Redisual Energy H16'!F10-'Sys Redisual Energy L08'!F10 -> 2573.1781 | F11: =(SUMPRODUCT(OFFSET('BlocksFinal (Kyle and Naser)'!$A10,0,(F$1-1)*10+5,1,5),{2,6,8,6,2}))*$B11/1000-'Sys Redisual Energy H16'!G10-'Sys Redisual Energy L08'!G10 -> 1035.1798 | G11: =(SUMPRODUCT(OFFSET('BlocksFinal (Kyle and Naser)'!$A10,0,(G$1-1)*10+5,1,5),{2,6,8,6,2}))*$B11/1000-'Sys Redisual Energy H16'!H10-'Sys Redisual Energy L08'!H10 -> 1981.2354 | H11: =(SUMPRODUCT(OFFSET('BlocksFinal (Kyle and Naser)'!$A10,0,(H$1-1)*10+5,1,5),{2,6,8,6,2}))*$B11/1000-'Sys Redisual Energy H16'!I10-'Sys Redisual Energy L08'!I10 -> 2077.1161 | I11: =(SUMPRODUCT(OFFSET('BlocksFinal (Kyle and Naser)'!$A10,0,(I$1-1)*10+5,1,5),{2,6,8,6,2}))*$B11/1000-'Sys Redisual Energy H16'!J10-'Sys Redisual Energy L08'!J10 -> 1814.7127 | J11: =(SUMPRODUCT(OFFSET('BlocksFinal (Kyle and Naser)'!$A10,0,(J$1-1)*10+5,1,5),{2,6,8,6,2}))*$B11/1000-'Sys Redisual Energy H16'!K10-'Sys Redisual Energy L08'!K10 -> 2346.1471 | ... AY11: =(SUMPRODUCT(OFFSET('BlocksFinal (Kyle and Naser)'!$A10,0,(AY$1-1)*10+5,1,5),{2,6,8,6,2}))*$B11/1000-'Sys Redisual Energy H16'!AZ10-'Sys Redisual Energy L08'!AZ10 -> 2105.4441
A12: 44835 | B12: =A13-A12 -> 31 | C12: =(SUMPRODUCT(OFFSET('BlocksFinal (Kyle and Naser)'!$A11,0,(C$1-1)*10+5,1,5),{2,6,8,6,2}))*$B12/1000-'Sys Redisual Energy H16'!D11-'Sys Redisual Energy L08'!D11 -> 298.75646 | D12: =(SUMPRODUCT(OFFSET('BlocksFinal (Kyle and Naser)'!$A11,0,(D$1-1)*10+5,1,5),{2,6,8,6,2}))*$B12/1000-'Sys Redisual Energy H16'!E11-'Sys Redisual Energy L08'!E11 -> 1614.4673 | E12: =(SUMPRODUCT(OFFSET('BlocksFinal (Kyle and Naser)'!$A11,0,(E$1-1)*10+5,1,5),{2,6,8,6,2}))*$B12/1000-'Sys Redisual Energy H16'!F11-'Sys Redisual Energy L08'!F11 -> 1178.7851 | F12: =(SUMPRODUCT(OFFSET('BlocksFinal (Kyle and Naser)'!$A11,0,(F$1-1)*10+5,1,5),{2,6,8,6,2}))*$B12/1000-'Sys Redisual Energy H16'!G11-'Sys Redisual Energy L08'!G11 -> 1148.9458 | G12: =(SUMPRODUCT(OFFSET('BlocksFinal (Kyle and Naser)'!$A11,0,(G$1-1)*10+5,1,5),{2,6,8,6,2}))*$B12/1000-'Sys Redisual Energy H16'!H11-'Sys Redisual Energy L08'!H11 -> 829.51604 | H12: =(SUMPRODUCT(OFFSET('BlocksFinal (Kyle and Naser)'!$A11,0,(H$1-1)*10+5,1,5),{2,6,8,6,2}))*$B12/1000-'Sys Redisual Energy H16'!I11-'Sys Redisual Energy L08'!I11 -> 1939.736 | I12: =(SUMPRODUCT(OFFSET('BlocksFinal (Kyle and Naser)'!$A11,0,(I$1-1)*10+5,1,5),{2,6,8,6,2}))*$B12/1000-'Sys Redisual Energy H16'!J11-'Sys Redisual Energy L08'!J11 -> 1192.2383 | J12: =(SUMPRODUCT(OFFSET('BlocksFinal (Kyle and Naser)'!$A11,0,(J$1-1)*10+5,1,5),{2,6,8,6,2}))*$B12/1000-'Sys Redisual Energy H16'!K11-'Sys Redisual Energy L08'!K11 -> 411.18948 | ... AY12: =(SUMPRODUCT(OFFSET('BlocksFinal (Kyle and Naser)'!$A11,0,(AY$1-1)*10+5,1,5),{2,6,8,6,2}))*$B12/1000-'Sys Redisual Energy H16'!AZ11-'Sys Redisual Energy L08'!AZ11 -> 566.65567
A13: 44866 | B13: =A14-A13 -> 30 | C13: =(SUMPRODUCT(OFFSET('BlocksFinal (Kyle and Naser)'!$A12,0,(C$1-1)*10+5,1,5),{2,6,8,6,2}))*$B13/1000-'Sys Redisual Energy H16'!D12-'Sys Redisual Energy L08'!D12 -> 886.21717 | D13: =(SUMPRODUCT(OFFSET('BlocksFinal (Kyle and Naser)'!$A12,0,(D$1-1)*10+5,1,5),{2,6,8,6,2}))*$B13/1000-'Sys Redisual Energy H16'!E12-'Sys Redisual Energy L08'!E12 -> 188.91197 | E13: =(SUMPRODUCT(OFFSET('BlocksFinal (Kyle and Naser)'!$A12,0,(E$1-1)*10+5,1,5),{2,6,8,6,2}))*$B13/1000-'Sys Redisual Energy H16'!F12-'Sys Redisual Energy L08'!F12 -> 1212.2572 | F13: =(SUMPRODUCT(OFFSET('BlocksFinal (Kyle and Naser)'!$A12,0,(F$1-1)*10+5,1,5),{2,6,8,6,2}))*$B13/1000-'Sys Redisual Energy H16'!G12-'Sys Redisual Energy L08'!G12 -> 332.92205 | G13: =(SUMPRODUCT(OFFSET('BlocksFinal (Kyle and Naser)'!$A12,0,(G$1-1)*10+5,1,5),{2,6,8,6,2}))*$B13/1000-'Sys Redisual Energy H16'!H12-'Sys Redisual Energy L08'!H12 -> 781.88747 | H13: =(SUMPRODUCT(OFFSET('BlocksFinal (Kyle and Naser)'!$A12,0,(H$1-1)*10+5,1,5),{2,6,8,6,2}))*$B13/1000-'Sys Redisual Energy H16'!I12-'Sys Redisual Energy L08'!I12 -> 51.188973 | I13: =(SUMPRODUCT(OFFSET('BlocksFinal (Kyle and Naser)'!$A12,0,(I$1-1)*10+5,1,5),{2,6,8,6,2}))*$B13/1000-'Sys Redisual Energy H16'!J12-'Sys Redisual Energy L08'!J12 -> -405.52461 | J13: =(SUMPRODUCT(OFFSET('BlocksFinal (Kyle and Naser)'!$A12,0,(J$1-1)*10+5,1,5),{2,6,8,6,2}))*$B13/1000-'Sys Redisual Energy H16'!K12-'Sys Redisual Energy L08'!K12 -> 583.25257 | ... AY13: =(SUMPRODUCT(OFFSET('BlocksFinal (Kyle and Naser)'!$A12,0,(AY$1-1)*10+5,1,5),{2,6,8,6,2}))*$B13/1000-'Sys Redisual Energy H16'!AZ12-'Sys Redisual Energy L08'!AZ12 -> -648.43472
... A61: 46327 | B61: =A62-A61 -> 30 | C61: =(SUMPRODUCT(OFFSET('BlocksFinal (Kyle and Naser)'!$A60,0,(C$1-1)*10+5,1,5),{2,6,8,6,2}))*$B61/1000-'Sys Redisual Energy H16'!D60-'Sys Redisual Energy L08'!D60 -> 309.36072 | D61: =(SUMPRODUCT(OFFSET('BlocksFinal (Kyle and Naser)'!$A60,0,(D$1-1)*10+5,1,5),{2,6,8,6,2}))*$B61/1000-'Sys Redisual Energy H16'!E60-'Sys Redisual Energy L08'!E60 -> 300.79955 | E61: =(SUMPRODUCT(OFFSET('BlocksFinal (Kyle and Naser)'!$A60,0,(E$1-1)*10+5,1,5),{2,6,8,6,2}))*$B61/1000-'Sys Redisual Energy H16'!F60-'Sys Redisual Energy L08'!F60 -> -401.55894 | F61: =(SUMPRODUCT(OFFSET('BlocksFinal (Kyle and Naser)'!$A60,0,(F$1-1)*10+5,1,5),{2,6,8,6,2}))*$B61/1000-'Sys Redisual Energy H16'!G60-'Sys Redisual Energy L08'!G60 -> -647.92004 | G61: =(SUMPRODUCT(OFFSET('BlocksFinal (Kyle and Naser)'!$A60,0,(G$1-1)*10+5,1,5),{2,6,8,6,2}))*$B61/1000-'Sys Redisual Energy H16'!H60-'Sys Redisual Energy L08'!H60 -> 1060.8545 | H61: =(SUMPRODUCT(OFFSET('BlocksFinal (Kyle and Naser)'!$A60,0,(H$1-1)*10+5,1,5),{2,6,8,6,2}))*$B61/1000-'Sys Redisual Energy H16'!I60-'Sys Redisual Energy L08'!I60 -> -572.02437 | I61: =(SUMPRODUCT(OFFSET('BlocksFinal (Kyle and Naser)'!$A60,0,(I$1-1)*10+5,1,5),{2,6,8,6,2}))*$B61/1000-'Sys Redisual Energy H16'!J60-'Sys Redisual Energy L08'!J60 -> 290.22953 | J61: =(SUMPRODUCT(OFFSET('BlocksFinal (Kyle and Naser)'!$A60,0,(J$1-1)*10+5,1,5),{2,6,8,6,2}))*$B61/1000-'Sys Redisual Energy H16'!K60-'Sys Redisual Energy L08'!K60 -> 138.47088 | ... AY61: =(SUMPRODUCT(OFFSET('BlocksFinal (Kyle and Naser)'!$A60,0,(AY$1-1)*10+5,1,5),{2,6,8,6,2}))*$B61/1000-'Sys Redisual Energy H16'!AZ60-'Sys Redisual Energy L08'!AZ60 -> 112.04723
A62: 46357

Sheet BlocksFinal (Kyle and Naser)
A1: 64.555373 | B1: 55.81244 | C1: 44.145629 | D1: 37.650469 | E1: 25.224489 | F1: 4469.911 | G1: 4429.9574 | H1: 4119.3379 | I1: 3362.4216 | J1: 2942.4112 | K1: 92.535671 | L1: 70.161135 | M1: 53.453232 | N1: 45.125211 | O1: 26.652764 | P1: 4723.3139 | Q1: 4880.6038 | R1: 4296.2434 | S1: 3399.6633 | T1: 3064.4595 | U1: 54.553621 | V1: 41.411371 | W1: 32.866984 | X1: 28.762428 | Y1: 20.27772 | Z1: 4864.9314 | AA1: 4624.6443 | AB1: 4023.1996 | AC1: 2275.9889 | AD1: 3193.5771 | AE1: 72.974974 | AF1: 59.036651 | AG1: 46.692944 | AH1: 41.47517 | AI1: 26.734157 | AJ1: 4767.0294 | AK1: 4747.8854 | AL1: 4190.6448 | AM1: 4310.5529 | AN1: 2955.1568 | AO1: 68.675738 | AP1: 52.386156 | AQ1: 41.576855 | AR1: 37.884524 | AS1: 26.402955 | AT1: 4840.6983 | AU1: 5154.0105 | AV1: 4786.6881 | AW1: 6077.6767 | AX1: 2887.8405 | AY1: 56.863042 | AZ1: 47.505145 | BA1: 39.233563 | BB1: 33.601805 | BC1: 23.014233 | BD1: 5682.9729 | BE1: 5475.816 | BF1: 4970.718 | BG1: 5535.1511 | BH1: 3742.6536 | BI1: 68.271228 | BJ1: 54.988264 | BK1: 44.784344 | BL1: 38.968781 | BM1: 26.648731 | BN1: 4785.2144 | BO1: 4654.9081 | BP1: 4321.4663 | BQ1: 4573.8655 | BR1: 2993.6236 | BS1: 63.674431 | BT1: 51.629581 | BU1: 43.437482 | BV1: 39.152291 | BW1: 25.749757 | BX1: 3981.7858 | BY1: 4084.5697 | BZ1: 3882.7319 | CA1: 4743.3316 | CB1: 2640.7189 | CC1: 69.26126 | CD1: 58.802105 | CE1: 47.177978 | CF1: 40.977273 | CG1: 24.808906 | CH1: 5234.7835 | CI1: 5025.5056 | CJ1: 4542.1403 | CK1: 3378.2793 | CL1: 2940.9006 | CM1: 72.467997 | CN1: 64.037011 | CO1: 51.651376 | CP1: 45.053192 | CQ1: 25.238241 | CR1: 5147.5583 | CS1: 5082.6474 | CT1: 4670.6361 | CU1: 3561.6326 | CV1: 3023.6564 | CW1: 86.548384 | CX1: 67.254397 | CY1: 53.650199 | CZ1: 45.143909 | DA1: 26.760077 | DB1: 5838.6793 | DC1: 5619.4219 | DD1: 5149.4779 | DE1: 3674.2989 | DF1: 3011.4584 | DG1: 86.421159 | DH1: 70.416442 | DI1: 57.248146 | DJ1: 49.054796 | DK1: 26.760077 | DL1: 5968.5238 | DM1: 5742.1601 | DN1: 5231.5851 | DO1: 6545.075 | DP1: 3300.0556 | DQ1: 77.58598 | DR1: 55.89751 | DS1: 44.508595 | DT1: 40.429432 | DU1: 25.559456 | DV1: 5561.1114 | DW1: 5319.2076 | DX1: 5117.095 | DY1: 5951.9146 | DZ1: 3284.0484 | EA1: 72.554566 | EB1: 55.763584 | EC1: 42.251568 | ED1: 38.733376 | EE1: 26.558922 | EF1: 5079.5995 | EG1: 4873.9544 | EH1: 4376.1957 | EI1: 4274.5976 | EJ1: 2976.2384 | EK1: 73.08105 | EL1: 61.10405 | EM1: 49.767841 | EN1: 40.310184 | EO1: 26.37949 | EP1: 5191.0987 | EQ1: 5061.6697 | ER1: 4773.4681 | ES1: 5051.5149 | ET1: 3109.0457 | EU1: 65.827671 | EV1: 54.150702 | EW1: 43.166746 | EX1: 38.516727 | EY1: 25.509639 | EZ1: 5200.1604 | FA1: 4898.1931 | FB1: 4472.2057 | FC1: 4996.3 | FD1: 2991.6133 | FE1: 58.660428 | FF1: 48.758944 | FG1: 40.229549 | FH1: 37.274868 | FI1: 25.685777 | FJ1: 4674.385 | FK1: 4287.0877 | FL1: 4367.7526 | FM1: 3820.6029 | FN1: 2744.1799 | FO1: 67.446927 | FP1: 54.788634 | FQ1: 45.768179 | FR1: 41.046039 | FS1: 25.97929 | FT1: 6000.8388 | FU1: 5385.6643 | FV1: 5110.6314 | FW1: 4266.1111 | FX1: 2933.7318 | FY1: 73.849699 | FZ1: 54.480823 | GA1: 40.635779 | GB1: 34.944791 | GC1: 23.256878 | GD1: 4862.1225 | GE1: 4491.7811 | GF1: 4158.6435 | GG1: 4027.289 | GH1: 3168.4084 | GI1: 61.365756 | GJ1: 47.037739 | GK1: 36.92048 | GL1: 32.900537 | GM1: 24.632805 | GN1: 5871.5246 | GO1: 5387.7442 | GP1: 4697.324 | GQ1: 3723.6348 | GR1: 3659.0811 | GS1: 80.06669 | GT1: 63.021599 | GU1: 47.087164 | GV1: 39.270424 | GW1: 24.446506 | GX1: 5392.8081 | GY1: 5095.6012 | GZ1: 4659.1915 | HA1: 4512.1749 | HB1: 3064.8808 | HC1: 57.517841 | HD1: 46.141343 | HE1: 37.408424 | HF1: 33.68435 | HG1: 25.146749 | HH1: 4986.0627 | HI1: 4597.6488 | HJ1: 4170.7457 | HK1: 4483.7715 | HL1: 3037.5161 | HM1: 68.510345 | HN1: 57.692977 | HO1: 44.854421 | HP1: 38.106045 | HQ1: 23.876561 | HR1: 4328.4356 | HS1: 4356.7473 | HT1: 4142.5721 | HU1: 2922.3777 | HV1: 3109.8454 | HW1: 73.047184 | HX1: 60.344677 | HY1: 46.449635 | HZ1: 40.85288 | IA1: 25.799099 | IB1: 5842.2813 | IC1: 5862.6423 | ID1: 5354.4695 | IE1: 4250.9907 | IF1: 3140.8294 | IG1: 80.460098 | IH1: 64.560042 | II1: 53.045322 | IJ1: 45.929036 | IK1: 26.760077 | IL1: 4968.5097 | IM1: 4586.3534 | IN1: 4377.6095 | IO1: 3771.1349 | IP1: 2931.6588 | IQ1: 92.949484 | IR1: 61.555353 | IS1: 44.07292 | IT1: 36.305082 | IU1: 20.055208 | IV1: 5924.7537 | IW1: 4711.4047 | IX1: 4298.9827 | IY1: 3957.8293 | IZ1: 2926.0775 | JA1: 81.324794 | JB1: 62.308019 | JC1: 41.731508 | JD1: 32.800047 | JE1: 20.082087 | JF1: 4703.5858 | JG1: 4607.2858 | JH1: 4225.2078 | JI1: 3765.8413 | JJ1: 3567.8564 | JK1: 86.715079 | JL1: 73.133632 | JM1: 60.727776 | JN1: 52.239372 | JO1: 26.760077 | JP1: 5342.3324 | JQ1: 5223.6718 | JR1: 5257.0708 | JS1: 4250.7346 | JT1: 3201.6835 | JU1: 74.816481 | JV1: 58.618711 | JW1: 43.721455 | JX1: 34.147551 | JY1: 22.83031 | JZ1: 4904.0619 | KA1: 4898.4211 | KB1: 4453.1983 | KC1: 4556.6107 | KD1: 3541.5841 | KE1: 82.609437 | KF1: 63.640035 | KG1: 49.766926 | KH1: 42.219503 | KI1: 26.160669 | KJ1: 4764.913 | KK1: 4734.8248 | KL1: 4502.9605 | KM1: 3961.0599 | KN1: 3158.7668 | KO1: 66.35269 | KP1: 56.479911 | KQ1: 45.601251 | KR1: 39.904514 | KS1: 26.745725 | KT1: 5078.0465 | KU1: 4888.837 | KV1: 4437.5818 | KW1: 4514.4847 | KX1: 2985.5983 | KY1: 70.252748 | KZ1: 55.646109 | LA1: 40.382938 | LB1: 34.101135 | LC1: 23.212109 | LD1: 4134.1187 | LE1: 4247.947 | LF1: 3965.103 | LG1: 4771.0865 | LH1: 3066.6621 | LI1: 60.831475 | LJ1: 48.179193 | LK1: 38.303334 | LL1: 34.442028 | LM1: 22.132684 | LN1: 5091.063 | LO1: 4541.775 | LP1: 4030.8924 | LQ1: 4586.1968 | LR1: 3179.8996 | LS1: 65.203739 | LT1: 55.213713 | LU1: 41.180748 | LV1: 32.513989 | LW1: 22.793354 | LX1: 4869.4867 | LY1: 4590.6166 | LZ1: 4348.0049 | MA1: 5309.1639 | MB1: 3335.8769 | MC1: 63.41179 | MD1: 49.774888 | ME1: 38.247554 | MF1: 33.902962 | MG1: 24.199007 | MH1: 5036.7193 | MI1: 4695.0771 | MJ1: 4518.1577 | MK1: 4306.4245 | ML1: 3614.2185 | MM1: 64.141902 | MN1: 53.072763 | MO1: 41.734774 | MP1: 37.352591 | MQ1: 25.123299 | MR1: 6302.1696 | MS1: 5836.8932 | MT1: 5187.7464 | MU1: 4510.1352 | MV1: 2974.6507 | MW1: 68.531447 | MX1: 54.989242 | MY1: 44.815656 | MZ1: 38.854342 | NA1: 24.705899 | NB1: 5067.4432 | NC1: 5037.9456 | ND1: 4968.0034 | NE1: 4058.0943 | NF1: 3252.0629 | NG1: 66.096269 | NH1: 53.626963 | NI1: 40.930464 | NJ1: 36.305118 | NK1: 26.040946 | NL1: 5233.8713 | NM1: 4612.9711 | NN1: 4207.7811 | NO1: 4165.4386 | NP1: 3135.8439 | NQ1: 86.142814 | NR1: 67.914097 | NS1: 53.65994 | NT1: 44.597159 | NU1: 26.760077 | NV1: 4821.2561 | NW1: 4846.3128 | NX1: 4740.3297 | NY1: 3473.0229 | NZ1: 3133.416 | OA1: 66.49283 | OB1: 57.553923 | OC1: 44.343149 | OD1: 37.89408 | OE1: 24.353284 | OF1: 5036.4641 | OG1: 4975.6749 | OH1: 4570.5501 | OI1: 3741.2847 | OJ1: 3123.2928 | OK1: 87.857874 | OL1: 75.026143 | OM1: 61.649926 | ON1: 53.907433 | OO1: 26.760077 | OP1: 5055.0248 | OQ1: 5081.6002 | OR1: 5207.1506 | OS1: 5519.2354 | OT1: 3276.1747 | OU1: 57.171764 | OV1: 44.715921 | OW1: 37.09569 | OX1: 33.285009 | OY1: 20.861042 | OZ1: 4783.2529 | PA1: 4113.3902 | PB1: 3894.2498 | PC1: 3387.3549 | PD1: 3215.7887 | PE1: 50.795228 | PF1: 38.148213 | PG1: 32.386257 | PH1: 29.458277 | PI1: 19.712399 | PJ1: 4543.7308 | PK1: 4577.0996 | PL1: 4163.6977 | PM1: 3403.4058 | PN1: 3354.6766 | PO1: 71.157536 | PP1: 55.767782 | PQ1: 43.660439 | PR1: 39.215982 | PS1: 26.392484 | PT1: 5997.3798 | PU1: 5608.0424 | PV1: 4876.4401 | PW1: 3573.2834 | PX1: 2890.9874 | PY1: 65.943838 | PZ1: 58.632685 | QA1: 47.443222 | QB1: 39.850802 | QC1: 26.565366 | QD1: 5182.1172 | QE1: 4941.2744 | QF1: 4902.9372 | QG1: 4017.6703 | QH1: 3018.5157 | QI1: 55.712238 | QJ1: 41.597643 | QK1: 33.497175 | QL1: 30.904434 | QM1: 23.627424 | QN1: 4907.303 | QO1: 4453.8853 | QP1: 4228.668 | QQ1: 4451.9505 | QR1: 3317.265 | QS1: 86.151041 | QT1: 70.846114 | QU1: 59.523908 | QV1: 54.439986 | QW1: 26.760077 | QX1: 4952.8911 | QY1: 4676.0794 | QZ1: 4613.1264 | RA1: 5323.5697 | RB1: 3142.5364 | RC1: 66.475867 | RD1: 51.352017 | RE1: 42.296936 | RF1: 37.484947 | RG1: 25.149241 | RH1: 4689.0024 | RI1: 4324.2465 | RJ1: 4334.4236 | RK1: 4322.1656 | RL1: 2911.2807 | RM1: 82.551326 | RN1: 64.695876 | RO1: 45.593038 | RP1: 37.678139 | RQ1: 25.496664 | RR1: 5725.2463 | RS1: 5444.6173 | RT1: 4562.9544 | RU1: 4336.3128 | RV1: 3046.661
